2025-05-11 22:53:45,092 - ERROR - Analiz Detay Sayfasý Hatasý (ID: 4): 'csrf_token' is undefined
Traceback (most recent call last):
  File "c:\Users\ustad\Desktop\arsaanalizvesunum\app.py", line 1854, in analiz_detay
    return render_template(
  File "C:\Users\ustad\Desktop\arsaanalizvesunum\venv\lib\site-packages\flask\templating.py", line 147, in render_template
    return _render(
  File "C:\Users\ustad\Desktop\arsaanalizvesunum\venv\lib\site-packages\flask\templating.py", line 128, in _render
    rv = template.render(context)
  File "C:\Users\ustad\Desktop\arsaanalizvesunum\venv\lib\site-packages\jinja2\environment.py", line 1295, in render
    self.environment.handle_exception()
  File "C:\Users\ustad\Desktop\arsaanalizvesunum\venv\lib\site-packages\jinja2\environment.py", line 942, in handle_exception
    raise rewrite_traceback_stack(source=source)
  File "c:\Users\ustad\Desktop\arsaanalizvesunum\templates\analiz_detay.html", line 656, in top-level template code
    // formData.append('csrf_token', '{{ csrf_token() }}');
  File "C:\Users\ustad\Desktop\arsaanalizvesunum\venv\lib\site-packages\jinja2\utils.py", line 92, in from_obj
    if hasattr(obj, "jinja_pass_arg"):
jinja2.exceptions.UndefinedError: 'csrf_token' is undefined
2025-05-11 22:53:47,488 - ERROR - Analiz Detay Sayfasý Hatasý (ID: 4): 'csrf_token' is undefined
Traceback (most recent call last):
  File "c:\Users\ustad\Desktop\arsaanalizvesunum\app.py", line 1854, in analiz_detay
    return render_template(
  File "C:\Users\ustad\Desktop\arsaanalizvesunum\venv\lib\site-packages\flask\templating.py", line 147, in render_template
    return _render(
  File "C:\Users\ustad\Desktop\arsaanalizvesunum\venv\lib\site-packages\flask\templating.py", line 128, in _render
    rv = template.render(context)
  File "C:\Users\ustad\Desktop\arsaanalizvesunum\venv\lib\site-packages\jinja2\environment.py", line 1295, in render
    self.environment.handle_exception()
  File "C:\Users\ustad\Desktop\arsaanalizvesunum\venv\lib\site-packages\jinja2\environment.py", line 942, in handle_exception
    raise rewrite_traceback_stack(source=source)
  File "c:\Users\ustad\Desktop\arsaanalizvesunum\templates\analiz_detay.html", line 656, in top-level template code
    // formData.append('csrf_token', '{{ csrf_token() }}');
  File "C:\Users\ustad\Desktop\arsaanalizvesunum\venv\lib\site-packages\jinja2\utils.py", line 92, in from_obj
    if hasattr(obj, "jinja_pass_arg"):
jinja2.exceptions.UndefinedError: 'csrf_token' is undefined
2025-05-11 22:54:25,938 - ERROR - Analiz Detay Sayfasý Hatasý (ID: 4): 'csrf_token' is undefined
Traceback (most recent call last):
  File "c:\Users\ustad\Desktop\arsaanalizvesunum\app.py", line 1854, in analiz_detay
    return render_template(
  File "C:\Users\ustad\Desktop\arsaanalizvesunum\venv\lib\site-packages\flask\templating.py", line 147, in render_template
    return _render(
  File "C:\Users\ustad\Desktop\arsaanalizvesunum\venv\lib\site-packages\flask\templating.py", line 128, in _render
    rv = template.render(context)
  File "C:\Users\ustad\Desktop\arsaanalizvesunum\venv\lib\site-packages\jinja2\environment.py", line 1295, in render
    self.environment.handle_exception()
  File "C:\Users\ustad\Desktop\arsaanalizvesunum\venv\lib\site-packages\jinja2\environment.py", line 942, in handle_exception
    raise rewrite_traceback_stack(source=source)
  File "c:\Users\ustad\Desktop\arsaanalizvesunum\templates\analiz_detay.html", line 654, in top-level template code
    // formData.append('csrf_token', '{{ csrf_token() }}');
  File "C:\Users\ustad\Desktop\arsaanalizvesunum\venv\lib\site-packages\jinja2\utils.py", line 92, in from_obj
    if hasattr(obj, "jinja_pass_arg"):
jinja2.exceptions.UndefinedError: 'csrf_token' is undefined
2025-05-11 22:57:14,474 - ERROR - Sunucu hatasý: 404 Not Found: The requested URL was not found on the server. If you entered the URL manually please check your spelling and try again.
Traceback (most recent call last):
  File "C:\Users\ustad\Desktop\arsaanalizvesunum\venv\lib\site-packages\flask\app.py", line 1513, in full_dispatch_request
    rv = self.dispatch_request()
  File "C:\Users\ustad\Desktop\arsaanalizvesunum\venv\lib\site-packages\flask\app.py", line 1499, in dispatch_request
    return self.ensure_sync(self.view_functions[rule.endpoint])(**req.view_args)
  File "C:\Users\ustad\Desktop\arsaanalizvesunum\venv\lib\site-packages\flask\app.py", line 518, in <lambda>
    view_func=lambda **kw: self_ref().send_static_file(**kw),  # type: ignore # noqa: B950
  File "C:\Users\ustad\Desktop\arsaanalizvesunum\venv\lib\site-packages\flask\scaffold.py", line 328, in send_static_file
    return send_from_directory(
  File "C:\Users\ustad\Desktop\arsaanalizvesunum\venv\lib\site-packages\flask\helpers.py", line 700, in send_from_directory
    return werkzeug.utils.send_from_directory(  # type: ignore
  File "C:\Users\ustad\Desktop\arsaanalizvesunum\venv\lib\site-packages\werkzeug\utils.py", line 841, in send_from_directory
    raise NotFound()
werkzeug.exceptions.NotFound: 404 Not Found: The requested URL was not found on the server. If you entered the URL manually please check your spelling and try again.
2025-05-11 22:57:14,476 - ERROR - Sunucu hatasý: 404 Not Found: The requested URL was not found on the server. If you entered the URL manually please check your spelling and try again.
Traceback (most recent call last):
  File "C:\Users\ustad\Desktop\arsaanalizvesunum\venv\lib\site-packages\flask\app.py", line 1513, in full_dispatch_request
    rv = self.dispatch_request()
  File "C:\Users\ustad\Desktop\arsaanalizvesunum\venv\lib\site-packages\flask\app.py", line 1499, in dispatch_request
    return self.ensure_sync(self.view_functions[rule.endpoint])(**req.view_args)
  File "C:\Users\ustad\Desktop\arsaanalizvesunum\venv\lib\site-packages\flask\app.py", line 518, in <lambda>
    view_func=lambda **kw: self_ref().send_static_file(**kw),  # type: ignore # noqa: B950
  File "C:\Users\ustad\Desktop\arsaanalizvesunum\venv\lib\site-packages\flask\scaffold.py", line 328, in send_static_file
    return send_from_directory(
  File "C:\Users\ustad\Desktop\arsaanalizvesunum\venv\lib\site-packages\flask\helpers.py", line 700, in send_from_directory
    return werkzeug.utils.send_from_directory(  # type: ignore
  File "C:\Users\ustad\Desktop\arsaanalizvesunum\venv\lib\site-packages\werkzeug\utils.py", line 841, in send_from_directory
    raise NotFound()
werkzeug.exceptions.NotFound: 404 Not Found: The requested URL was not found on the server. If you entered the URL manually please check your spelling and try again.
2025-05-11 22:57:14,953 - ERROR - Sunucu hatasý: 404 Not Found: The requested URL was not found on the server. If you entered the URL manually please check your spelling and try again.
Traceback (most recent call last):
  File "C:\Users\ustad\Desktop\arsaanalizvesunum\venv\lib\site-packages\flask\app.py", line 1513, in full_dispatch_request
    rv = self.dispatch_request()
  File "C:\Users\ustad\Desktop\arsaanalizvesunum\venv\lib\site-packages\flask\app.py", line 1499, in dispatch_request
    return self.ensure_sync(self.view_functions[rule.endpoint])(**req.view_args)
  File "C:\Users\ustad\Desktop\arsaanalizvesunum\venv\lib\site-packages\flask\app.py", line 518, in <lambda>
    view_func=lambda **kw: self_ref().send_static_file(**kw),  # type: ignore # noqa: B950
  File "C:\Users\ustad\Desktop\arsaanalizvesunum\venv\lib\site-packages\flask\scaffold.py", line 328, in send_static_file
    return send_from_directory(
  File "C:\Users\ustad\Desktop\arsaanalizvesunum\venv\lib\site-packages\flask\helpers.py", line 700, in send_from_directory
    return werkzeug.utils.send_from_directory(  # type: ignore
  File "C:\Users\ustad\Desktop\arsaanalizvesunum\venv\lib\site-packages\werkzeug\utils.py", line 841, in send_from_directory
    raise NotFound()
werkzeug.exceptions.NotFound: 404 Not Found: The requested URL was not found on the server. If you entered the URL manually please check your spelling and try again.
2025-05-11 22:57:14,955 - ERROR - Sunucu hatasý: 404 Not Found: The requested URL was not found on the server. If you entered the URL manually please check your spelling and try again.
Traceback (most recent call last):
  File "C:\Users\ustad\Desktop\arsaanalizvesunum\venv\lib\site-packages\flask\app.py", line 1513, in full_dispatch_request
    rv = self.dispatch_request()
  File "C:\Users\ustad\Desktop\arsaanalizvesunum\venv\lib\site-packages\flask\app.py", line 1499, in dispatch_request
    return self.ensure_sync(self.view_functions[rule.endpoint])(**req.view_args)
  File "C:\Users\ustad\Desktop\arsaanalizvesunum\venv\lib\site-packages\flask\app.py", line 518, in <lambda>
    view_func=lambda **kw: self_ref().send_static_file(**kw),  # type: ignore # noqa: B950
  File "C:\Users\ustad\Desktop\arsaanalizvesunum\venv\lib\site-packages\flask\scaffold.py", line 328, in send_static_file
    return send_from_directory(
  File "C:\Users\ustad\Desktop\arsaanalizvesunum\venv\lib\site-packages\flask\helpers.py", line 700, in send_from_directory
    return werkzeug.utils.send_from_directory(  # type: ignore
  File "C:\Users\ustad\Desktop\arsaanalizvesunum\venv\lib\site-packages\werkzeug\utils.py", line 841, in send_from_directory
    raise NotFound()
werkzeug.exceptions.NotFound: 404 Not Found: The requested URL was not found on the server. If you entered the URL manually please check your spelling and try again.
2025-05-12 00:07:48,186 - ERROR - Analiz Detay Sayfasý Hatasý (ID: 10): Could not build url for endpoint 'analysis_form_edit' with values ['analiz_id']. Did you mean 'analysis_form' instead?
Traceback (most recent call last):
  File "c:\Users\ustad\Desktop\arsaanalizvesunum\app.py", line 1854, in analiz_detay
    return render_template(
  File "C:\Users\ustad\Desktop\arsaanalizvesunum\venv\lib\site-packages\flask\templating.py", line 147, in render_template
    return _render(
  File "C:\Users\ustad\Desktop\arsaanalizvesunum\venv\lib\site-packages\flask\templating.py", line 128, in _render
    rv = template.render(context)
  File "C:\Users\ustad\Desktop\arsaanalizvesunum\venv\lib\site-packages\jinja2\environment.py", line 1295, in render
    self.environment.handle_exception()
  File "C:\Users\ustad\Desktop\arsaanalizvesunum\venv\lib\site-packages\jinja2\environment.py", line 942, in handle_exception
    raise rewrite_traceback_stack(source=source)
  File "c:\Users\ustad\Desktop\arsaanalizvesunum\templates\analiz_detay.html", line 170, in top-level template code
    <a href="{{ url_for('analysis_form_edit', analiz_id=analiz.id) }}" class="btn btn-outline-secondary btn-sm me-2"> {# 'analysis_form_edit' route'unuzu kontrol edin #}
  File "C:\Users\ustad\Desktop\arsaanalizvesunum\venv\lib\site-packages\flask\helpers.py", line 338, in url_for
    return appctx.app.handle_url_build_error(error, endpoint, values)
  File "C:\Users\ustad\Desktop\arsaanalizvesunum\venv\lib\site-packages\flask\helpers.py", line 325, in url_for
    rv = url_adapter.build(
  File "C:\Users\ustad\Desktop\arsaanalizvesunum\venv\lib\site-packages\werkzeug\routing.py", line 2305, in build
    raise BuildError(endpoint, values, method, self)
werkzeug.routing.BuildError: Could not build url for endpoint 'analysis_form_edit' with values ['analiz_id']. Did you mean 'analysis_form' instead?
