2025-05-15 00:36:24,794 - ERROR - app - Sunucu hatası oluştu: 404 Not Found: The requested URL was not found on the server. If you entered the URL manually please check your spelling and try again.
Traceback:
Traceback (most recent call last):
  File "C:\Users\ustad\Desktop\arsaanalizvesunum\venv\lib\site-packages\flask\app.py", line 1513, in full_dispatch_request
    rv = self.dispatch_request()
  File "C:\Users\ustad\Desktop\arsaanalizvesunum\venv\lib\site-packages\flask\app.py", line 1489, in dispatch_request
    self.raise_routing_exception(req)
  File "C:\Users\ustad\Desktop\arsaanalizvesunum\venv\lib\site-packages\flask\app.py", line 1471, in raise_routing_exception
    raise request.routing_exception  # type: ignore
  File "C:\Users\ustad\Desktop\arsaanalizvesunum\venv\lib\site-packages\flask\ctx.py", line 367, in match_request
    result = self.url_adapter.match(return_rule=True)  # type: ignore
  File "C:\Users\ustad\Desktop\arsaanalizvesunum\venv\lib\site-packages\werkzeug\routing.py", line 2032, in match
    raise NotFound()
werkzeug.exceptions.NotFound: 404 Not Found: The requested URL was not found on the server. If you entered the URL manually please check your spelling and try again.

2025-05-15 00:36:49,843 - ERROR - app - Sunucu hatası oluştu: 404 Not Found: The requested URL was not found on the server. If you entered the URL manually please check your spelling and try again.
Traceback:
Traceback (most recent call last):
  File "C:\Users\ustad\Desktop\arsaanalizvesunum\venv\lib\site-packages\flask\app.py", line 1513, in full_dispatch_request
    rv = self.dispatch_request()
  File "C:\Users\ustad\Desktop\arsaanalizvesunum\venv\lib\site-packages\flask\app.py", line 1489, in dispatch_request
    self.raise_routing_exception(req)
  File "C:\Users\ustad\Desktop\arsaanalizvesunum\venv\lib\site-packages\flask\app.py", line 1471, in raise_routing_exception
    raise request.routing_exception  # type: ignore
  File "C:\Users\ustad\Desktop\arsaanalizvesunum\venv\lib\site-packages\flask\ctx.py", line 367, in match_request
    result = self.url_adapter.match(return_rule=True)  # type: ignore
  File "C:\Users\ustad\Desktop\arsaanalizvesunum\venv\lib\site-packages\werkzeug\routing.py", line 2032, in match
    raise NotFound()
werkzeug.exceptions.NotFound: 404 Not Found: The requested URL was not found on the server. If you entered the URL manually please check your spelling and try again.

2025-05-15 00:37:13,623 - ERROR - app - Sunucu hatası oluştu: (raised as a result of Query-invoked autoflush; consider using a session.no_autoflush block if this flush is occurring prematurely)
(pyodbc.ProgrammingError) ('42000', '[42000] [Microsoft][ODBC Driver 18 for SQL Server][SQL Server]The incoming tabular data stream (TDS) remote procedure call (RPC) protocol stream is incorrect. Parameter 8 (""): The supplied value is not a valid instance of data type float. Check the source data for invalid values. An example of an invalid value is data of numeric type with scale greater than precision. (8023) (SQLExecDirectW)')
[SQL: INSERT INTO dashboard_stats (user_id, toplam_arsa_sayisi, ortalama_fiyat, en_yuksek_fiyat, en_dusuk_fiyat, toplam_deger, ortalama_roi, son_guncelleme) OUTPUT inserted.id VALUES (?, ?, ?, ?, ?, ?, ?, ?)]
[parameters: (4, 0, 0.0, 0.0, inf, Decimal('0.00'), Decimal('0.00'), datetime.datetime(2025, 5, 14, 21, 37, 13, 589648))]
(Background on this error at: https://sqlalche.me/e/14/f405)
Traceback:
Traceback (most recent call last):
  File "C:\Users\ustad\Desktop\arsaanalizvesunum\venv\lib\site-packages\sqlalchemy\engine\base.py", line 1910, in _execute_context
    self.dialect.do_execute(
  File "C:\Users\ustad\Desktop\arsaanalizvesunum\venv\lib\site-packages\sqlalchemy\engine\default.py", line 736, in do_execute
    cursor.execute(statement, parameters)
pyodbc.ProgrammingError: ('42000', '[42000] [Microsoft][ODBC Driver 18 for SQL Server][SQL Server]The incoming tabular data stream (TDS) remote procedure call (RPC) protocol stream is incorrect. Parameter 8 (""): The supplied value is not a valid instance of data type float. Check the source data for invalid values. An example of an invalid value is data of numeric type with scale greater than precision. (8023) (SQLExecDirectW)')

The above exception was the direct cause of the following exception:

Traceback (most recent call last):
  File "C:\Users\ustad\Desktop\arsaanalizvesunum\venv\lib\site-packages\flask\app.py", line 1513, in full_dispatch_request
    rv = self.dispatch_request()
  File "C:\Users\ustad\Desktop\arsaanalizvesunum\venv\lib\site-packages\flask\app.py", line 1499, in dispatch_request
    return self.ensure_sync(self.view_functions[rule.endpoint])(**req.view_args)
  File "C:\Users\ustad\Desktop\arsaanalizvesunum\venv\lib\site-packages\flask_login\utils.py", line 290, in decorated_view
    return current_app.ensure_sync(func)(*args, **kwargs)
  File "c:\Users\ustad\Desktop\arsaanalizvesunum\blueprints\main_bp.py", line 71, in index
    ArsaAnaliz.query.filter_by(user_id=user_id)
  File "C:\Users\ustad\Desktop\arsaanalizvesunum\venv\lib\site-packages\sqlalchemy\orm\query.py", line 2773, in all
    return self._iter().all()
  File "C:\Users\ustad\Desktop\arsaanalizvesunum\venv\lib\site-packages\sqlalchemy\orm\query.py", line 2916, in _iter
    result = self.session.execute(
  File "C:\Users\ustad\Desktop\arsaanalizvesunum\venv\lib\site-packages\sqlalchemy\orm\session.py", line 1665, in execute
    ) = compile_state_cls.orm_pre_session_exec(
  File "C:\Users\ustad\Desktop\arsaanalizvesunum\venv\lib\site-packages\sqlalchemy\orm\context.py", line 312, in orm_pre_session_exec
    session._autoflush()
  File "C:\Users\ustad\Desktop\arsaanalizvesunum\venv\lib\site-packages\sqlalchemy\orm\session.py", line 2264, in _autoflush
    util.raise_(e, with_traceback=sys.exc_info()[2])
  File "C:\Users\ustad\Desktop\arsaanalizvesunum\venv\lib\site-packages\sqlalchemy\util\compat.py", line 211, in raise_
    raise exception
  File "C:\Users\ustad\Desktop\arsaanalizvesunum\venv\lib\site-packages\sqlalchemy\orm\session.py", line 2253, in _autoflush
    self.flush()
  File "C:\Users\ustad\Desktop\arsaanalizvesunum\venv\lib\site-packages\sqlalchemy\orm\session.py", line 3449, in flush
    self._flush(objects)
  File "C:\Users\ustad\Desktop\arsaanalizvesunum\venv\lib\site-packages\sqlalchemy\orm\session.py", line 3589, in _flush
    transaction.rollback(_capture_exception=True)
  File "C:\Users\ustad\Desktop\arsaanalizvesunum\venv\lib\site-packages\sqlalchemy\util\langhelpers.py", line 70, in __exit__
    compat.raise_(
  File "C:\Users\ustad\Desktop\arsaanalizvesunum\venv\lib\site-packages\sqlalchemy\util\compat.py", line 211, in raise_
    raise exception
  File "C:\Users\ustad\Desktop\arsaanalizvesunum\venv\lib\site-packages\sqlalchemy\orm\session.py", line 3549, in _flush
    flush_context.execute()
  File "C:\Users\ustad\Desktop\arsaanalizvesunum\venv\lib\site-packages\sqlalchemy\orm\unitofwork.py", line 456, in execute
    rec.execute(self)
  File "C:\Users\ustad\Desktop\arsaanalizvesunum\venv\lib\site-packages\sqlalchemy\orm\unitofwork.py", line 630, in execute
    util.preloaded.orm_persistence.save_obj(
  File "C:\Users\ustad\Desktop\arsaanalizvesunum\venv\lib\site-packages\sqlalchemy\orm\persistence.py", line 245, in save_obj
    _emit_insert_statements(
  File "C:\Users\ustad\Desktop\arsaanalizvesunum\venv\lib\site-packages\sqlalchemy\orm\persistence.py", line 1238, in _emit_insert_statements
    result = connection._execute_20(
  File "C:\Users\ustad\Desktop\arsaanalizvesunum\venv\lib\site-packages\sqlalchemy\engine\base.py", line 1710, in _execute_20
    return meth(self, args_10style, kwargs_10style, execution_options)
  File "C:\Users\ustad\Desktop\arsaanalizvesunum\venv\lib\site-packages\sqlalchemy\sql\elements.py", line 334, in _execute_on_connection
    return connection._execute_clauseelement(
  File "C:\Users\ustad\Desktop\arsaanalizvesunum\venv\lib\site-packages\sqlalchemy\engine\base.py", line 1577, in _execute_clauseelement
    ret = self._execute_context(
  File "C:\Users\ustad\Desktop\arsaanalizvesunum\venv\lib\site-packages\sqlalchemy\engine\base.py", line 1953, in _execute_context
    self._handle_dbapi_exception(
  File "C:\Users\ustad\Desktop\arsaanalizvesunum\venv\lib\site-packages\sqlalchemy\engine\base.py", line 2134, in _handle_dbapi_exception
    util.raise_(
  File "C:\Users\ustad\Desktop\arsaanalizvesunum\venv\lib\site-packages\sqlalchemy\util\compat.py", line 211, in raise_
    raise exception
  File "C:\Users\ustad\Desktop\arsaanalizvesunum\venv\lib\site-packages\sqlalchemy\engine\base.py", line 1910, in _execute_context
    self.dialect.do_execute(
  File "C:\Users\ustad\Desktop\arsaanalizvesunum\venv\lib\site-packages\sqlalchemy\engine\default.py", line 736, in do_execute
    cursor.execute(statement, parameters)
sqlalchemy.exc.ProgrammingError: (raised as a result of Query-invoked autoflush; consider using a session.no_autoflush block if this flush is occurring prematurely)
(pyodbc.ProgrammingError) ('42000', '[42000] [Microsoft][ODBC Driver 18 for SQL Server][SQL Server]The incoming tabular data stream (TDS) remote procedure call (RPC) protocol stream is incorrect. Parameter 8 (""): The supplied value is not a valid instance of data type float. Check the source data for invalid values. An example of an invalid value is data of numeric type with scale greater than precision. (8023) (SQLExecDirectW)')
[SQL: INSERT INTO dashboard_stats (user_id, toplam_arsa_sayisi, ortalama_fiyat, en_yuksek_fiyat, en_dusuk_fiyat, toplam_deger, ortalama_roi, son_guncelleme) OUTPUT inserted.id VALUES (?, ?, ?, ?, ?, ?, ?, ?)]
[parameters: (4, 0, 0.0, 0.0, inf, Decimal('0.00'), Decimal('0.00'), datetime.datetime(2025, 5, 14, 21, 37, 13, 589648))]
(Background on this error at: https://sqlalche.me/e/14/f405)

2025-05-15 00:37:17,052 - ERROR - app - Sunucu hatası oluştu: 404 Not Found: The requested URL was not found on the server. If you entered the URL manually please check your spelling and try again.
Traceback:
Traceback (most recent call last):
  File "C:\Users\ustad\Desktop\arsaanalizvesunum\venv\lib\site-packages\flask\app.py", line 1513, in full_dispatch_request
    rv = self.dispatch_request()
  File "C:\Users\ustad\Desktop\arsaanalizvesunum\venv\lib\site-packages\flask\app.py", line 1489, in dispatch_request
    self.raise_routing_exception(req)
  File "C:\Users\ustad\Desktop\arsaanalizvesunum\venv\lib\site-packages\flask\app.py", line 1471, in raise_routing_exception
    raise request.routing_exception  # type: ignore
  File "C:\Users\ustad\Desktop\arsaanalizvesunum\venv\lib\site-packages\flask\ctx.py", line 367, in match_request
    result = self.url_adapter.match(return_rule=True)  # type: ignore
  File "C:\Users\ustad\Desktop\arsaanalizvesunum\venv\lib\site-packages\werkzeug\routing.py", line 2032, in match
    raise NotFound()
werkzeug.exceptions.NotFound: 404 Not Found: The requested URL was not found on the server. If you entered the URL manually please check your spelling and try again.

2025-05-15 00:45:56,253 - INFO - app - Flask uygulaması başarıyla oluşturuldu ve yapılandırıldı.
2025-05-15 00:45:56,901 - ERROR - app - Sunucu hatası oluştu: 404 Not Found: The requested URL was not found on the server. If you entered the URL manually please check your spelling and try again.
Traceback:
Traceback (most recent call last):
  File "C:\Users\ustad\Desktop\arsaanalizvesunum\venv\lib\site-packages\flask\app.py", line 1513, in full_dispatch_request
    rv = self.dispatch_request()
  File "C:\Users\ustad\Desktop\arsaanalizvesunum\venv\lib\site-packages\flask\app.py", line 1489, in dispatch_request
    self.raise_routing_exception(req)
  File "C:\Users\ustad\Desktop\arsaanalizvesunum\venv\lib\site-packages\flask\app.py", line 1471, in raise_routing_exception
    raise request.routing_exception  # type: ignore
  File "C:\Users\ustad\Desktop\arsaanalizvesunum\venv\lib\site-packages\flask\ctx.py", line 367, in match_request
    result = self.url_adapter.match(return_rule=True)  # type: ignore
  File "C:\Users\ustad\Desktop\arsaanalizvesunum\venv\lib\site-packages\werkzeug\routing.py", line 2032, in match
    raise NotFound()
werkzeug.exceptions.NotFound: 404 Not Found: The requested URL was not found on the server. If you entered the URL manually please check your spelling and try again.

2025-05-15 00:45:59,499 - ERROR - app - Sunucu hatası oluştu: 'NoneType' object is not callable
Traceback:
Traceback (most recent call last):
  File "C:\Users\ustad\Desktop\arsaanalizvesunum\venv\lib\site-packages\flask\app.py", line 1513, in full_dispatch_request
    rv = self.dispatch_request()
  File "C:\Users\ustad\Desktop\arsaanalizvesunum\venv\lib\site-packages\flask\app.py", line 1499, in dispatch_request
    return self.ensure_sync(self.view_functions[rule.endpoint])(**req.view_args)
  File "C:\Users\ustad\Desktop\arsaanalizvesunum\venv\lib\site-packages\flask_login\utils.py", line 290, in decorated_view
    return current_app.ensure_sync(func)(*args, **kwargs)
  File "c:\Users\ustad\Desktop\arsaanalizvesunum\blueprints\main_bp.py", line 64, in index
    en_dusuk_fiyat=None(nullable=True), # İlk eklemede doğru ayarlanması için
TypeError: 'NoneType' object is not callable

2025-05-15 00:46:00,295 - ERROR - app - Sunucu hatası oluştu: 'NoneType' object is not callable
Traceback:
Traceback (most recent call last):
  File "C:\Users\ustad\Desktop\arsaanalizvesunum\venv\lib\site-packages\flask\app.py", line 1513, in full_dispatch_request
    rv = self.dispatch_request()
  File "C:\Users\ustad\Desktop\arsaanalizvesunum\venv\lib\site-packages\flask\app.py", line 1499, in dispatch_request
    return self.ensure_sync(self.view_functions[rule.endpoint])(**req.view_args)
  File "C:\Users\ustad\Desktop\arsaanalizvesunum\venv\lib\site-packages\flask_login\utils.py", line 290, in decorated_view
    return current_app.ensure_sync(func)(*args, **kwargs)
  File "c:\Users\ustad\Desktop\arsaanalizvesunum\blueprints\main_bp.py", line 64, in index
    en_dusuk_fiyat=None(nullable=True), # İlk eklemede doğru ayarlanması için
TypeError: 'NoneType' object is not callable

2025-05-15 00:46:17,668 - INFO - app - Flask uygulaması başarıyla oluşturuldu ve yapılandırıldı.
2025-05-15 00:46:35,533 - ERROR - app - Sunucu hatası oluştu: 404 Not Found: The requested URL was not found on the server. If you entered the URL manually please check your spelling and try again.
Traceback:
Traceback (most recent call last):
  File "C:\Users\ustad\Desktop\arsaanalizvesunum\venv\lib\site-packages\flask\app.py", line 1513, in full_dispatch_request
    rv = self.dispatch_request()
  File "C:\Users\ustad\Desktop\arsaanalizvesunum\venv\lib\site-packages\flask\app.py", line 1489, in dispatch_request
    self.raise_routing_exception(req)
  File "C:\Users\ustad\Desktop\arsaanalizvesunum\venv\lib\site-packages\flask\app.py", line 1471, in raise_routing_exception
    raise request.routing_exception  # type: ignore
  File "C:\Users\ustad\Desktop\arsaanalizvesunum\venv\lib\site-packages\flask\ctx.py", line 367, in match_request
    result = self.url_adapter.match(return_rule=True)  # type: ignore
  File "C:\Users\ustad\Desktop\arsaanalizvesunum\venv\lib\site-packages\werkzeug\routing.py", line 2032, in match
    raise NotFound()
werkzeug.exceptions.NotFound: 404 Not Found: The requested URL was not found on the server. If you entered the URL manually please check your spelling and try again.

2025-05-15 00:46:37,253 - ERROR - app - Sunucu hatası oluştu: 404 Not Found: The requested URL was not found on the server. If you entered the URL manually please check your spelling and try again.
Traceback:
Traceback (most recent call last):
  File "C:\Users\ustad\Desktop\arsaanalizvesunum\venv\lib\site-packages\flask\app.py", line 1513, in full_dispatch_request
    rv = self.dispatch_request()
  File "C:\Users\ustad\Desktop\arsaanalizvesunum\venv\lib\site-packages\flask\app.py", line 1499, in dispatch_request
    return self.ensure_sync(self.view_functions[rule.endpoint])(**req.view_args)
  File "C:\Users\ustad\Desktop\arsaanalizvesunum\venv\lib\site-packages\flask\app.py", line 518, in <lambda>
    view_func=lambda **kw: self_ref().send_static_file(**kw),  # type: ignore # noqa: B950
  File "C:\Users\ustad\Desktop\arsaanalizvesunum\venv\lib\site-packages\flask\scaffold.py", line 328, in send_static_file
    return send_from_directory(
  File "C:\Users\ustad\Desktop\arsaanalizvesunum\venv\lib\site-packages\flask\helpers.py", line 700, in send_from_directory
    return werkzeug.utils.send_from_directory(  # type: ignore
  File "C:\Users\ustad\Desktop\arsaanalizvesunum\venv\lib\site-packages\werkzeug\utils.py", line 841, in send_from_directory
    raise NotFound()
werkzeug.exceptions.NotFound: 404 Not Found: The requested URL was not found on the server. If you entered the URL manually please check your spelling and try again.

2025-05-15 00:46:37,770 - ERROR - app - Sunucu hatası oluştu: 404 Not Found: The requested URL was not found on the server. If you entered the URL manually please check your spelling and try again.
Traceback:
Traceback (most recent call last):
  File "C:\Users\ustad\Desktop\arsaanalizvesunum\venv\lib\site-packages\flask\app.py", line 1513, in full_dispatch_request
    rv = self.dispatch_request()
  File "C:\Users\ustad\Desktop\arsaanalizvesunum\venv\lib\site-packages\flask\app.py", line 1499, in dispatch_request
    return self.ensure_sync(self.view_functions[rule.endpoint])(**req.view_args)
  File "C:\Users\ustad\Desktop\arsaanalizvesunum\venv\lib\site-packages\flask\app.py", line 518, in <lambda>
    view_func=lambda **kw: self_ref().send_static_file(**kw),  # type: ignore # noqa: B950
  File "C:\Users\ustad\Desktop\arsaanalizvesunum\venv\lib\site-packages\flask\scaffold.py", line 328, in send_static_file
    return send_from_directory(
  File "C:\Users\ustad\Desktop\arsaanalizvesunum\venv\lib\site-packages\flask\helpers.py", line 700, in send_from_directory
    return werkzeug.utils.send_from_directory(  # type: ignore
  File "C:\Users\ustad\Desktop\arsaanalizvesunum\venv\lib\site-packages\werkzeug\utils.py", line 841, in send_from_directory
    raise NotFound()
werkzeug.exceptions.NotFound: 404 Not Found: The requested URL was not found on the server. If you entered the URL manually please check your spelling and try again.

2025-05-15 00:58:33,557 - INFO - app - Flask uygulaması başarıyla oluşturuldu ve yapılandırıldı.
2025-05-15 01:00:05,550 - INFO - app - Flask uygulaması başarıyla oluşturuldu ve yapılandırıldı.
2025-05-15 01:02:44,746 - INFO - app - Flask uygulaması başarıyla oluşturuldu ve yapılandırıldı.
2025-05-15 01:03:35,584 - INFO - app - Flask uygulaması başarıyla oluşturuldu ve yapılandırıldı.
2025-05-15 01:04:03,161 - INFO - app - Flask uygulaması başarıyla oluşturuldu ve yapılandırıldı.
2025-05-15 01:07:30,495 - INFO - app - Flask uygulaması başarıyla oluşturuldu ve yapılandırıldı.
2025-05-15 01:09:56,474 - INFO - app - Flask uygulaması başarıyla oluşturuldu ve yapılandırıldı.
2025-05-15 01:10:45,086 - INFO - app - Flask uygulaması başarıyla oluşturuldu ve yapılandırıldı.
2025-05-15 01:11:16,261 - INFO - app - Flask uygulaması başarıyla oluşturuldu ve yapılandırıldı.
2025-05-15 01:11:39,325 - INFO - app - Flask uygulaması başarıyla oluşturuldu ve yapılandırıldı.
2025-05-15 01:11:44,091 - INFO - app - Flask uygulaması başarıyla oluşturuldu ve yapılandırıldı.
2025-05-15 01:14:26,888 - INFO - app - Flask uygulaması başarıyla oluşturuldu ve yapılandırıldı.
2025-05-15 01:15:34,516 - INFO - app - Flask uygulaması başarıyla oluşturuldu ve yapılandırıldı.
2025-05-15 01:18:19,614 - INFO - app - Flask uygulaması başarıyla oluşturuldu ve yapılandırıldı.
2025-05-15 01:18:32,144 - INFO - app - Flask uygulaması başarıyla oluşturuldu ve yapılandırıldı.
2025-05-15 01:19:03,500 - INFO - app - Flask uygulaması başarıyla oluşturuldu ve yapılandırıldı.
2025-05-15 01:19:29,122 - INFO - app - Flask uygulaması başarıyla oluşturuldu ve yapılandırıldı.
2025-05-15 01:34:48,567 - INFO - app - Flask uygulaması başarıyla oluşturuldu ve yapılandırıldı.
2025-05-15 01:34:53,245 - INFO - app - Flask uygulaması başarıyla oluşturuldu ve yapılandırıldı.
2025-05-15 01:35:10,414 - ERROR - app - Sunucu hatası oluştu: Could not build url for endpoint 'admin.dashboard'. Did you mean 'crm.crm_team_dashboard' instead?
Traceback:
Traceback (most recent call last):
  File "C:\Users\ustad\Desktop\arsaanalizvesunum\venv\lib\site-packages\flask\app.py", line 1513, in full_dispatch_request
    rv = self.dispatch_request()
  File "C:\Users\ustad\Desktop\arsaanalizvesunum\venv\lib\site-packages\flask\app.py", line 1499, in dispatch_request
    return self.ensure_sync(self.view_functions[rule.endpoint])(**req.view_args)
  File "c:\Users\ustad\Desktop\arsaanalizvesunum\blueprints\auth_bp.py", line 49, in login
    return redirect(url_for('admin.dashboard'))
  File "C:\Users\ustad\Desktop\arsaanalizvesunum\venv\lib\site-packages\flask\helpers.py", line 338, in url_for
    return appctx.app.handle_url_build_error(error, endpoint, values)
  File "C:\Users\ustad\Desktop\arsaanalizvesunum\venv\lib\site-packages\flask\helpers.py", line 325, in url_for
    rv = url_adapter.build(
  File "C:\Users\ustad\Desktop\arsaanalizvesunum\venv\lib\site-packages\werkzeug\routing.py", line 2305, in build
    raise BuildError(endpoint, values, method, self)
werkzeug.routing.BuildError: Could not build url for endpoint 'admin.dashboard'. Did you mean 'crm.crm_team_dashboard' instead?

2025-05-15 01:40:45,883 - INFO - app - Flask uygulaması başarıyla oluşturuldu ve yapılandırıldı.
2025-05-15 01:40:50,823 - INFO - app - Flask uygulaması başarıyla oluşturuldu ve yapılandırıldı.
2025-05-15 01:41:12,902 - ERROR - app - Sunucu hatası oluştu: 404 Not Found: The requested URL was not found on the server. If you entered the URL manually please check your spelling and try again.
Traceback:
Traceback (most recent call last):
  File "C:\Users\ustad\Desktop\arsaanalizvesunum\venv\lib\site-packages\flask\app.py", line 1513, in full_dispatch_request
    rv = self.dispatch_request()
  File "C:\Users\ustad\Desktop\arsaanalizvesunum\venv\lib\site-packages\flask\app.py", line 1489, in dispatch_request
    self.raise_routing_exception(req)
  File "C:\Users\ustad\Desktop\arsaanalizvesunum\venv\lib\site-packages\flask\app.py", line 1471, in raise_routing_exception
    raise request.routing_exception  # type: ignore
  File "C:\Users\ustad\Desktop\arsaanalizvesunum\venv\lib\site-packages\flask\ctx.py", line 367, in match_request
    result = self.url_adapter.match(return_rule=True)  # type: ignore
  File "C:\Users\ustad\Desktop\arsaanalizvesunum\venv\lib\site-packages\werkzeug\routing.py", line 2032, in match
    raise NotFound()
werkzeug.exceptions.NotFound: 404 Not Found: The requested URL was not found on the server. If you entered the URL manually please check your spelling and try again.

2025-05-15 01:41:17,365 - ERROR - app - Sunucu hatası oluştu: 404 Not Found: The requested URL was not found on the server. If you entered the URL manually please check your spelling and try again.
Traceback:
Traceback (most recent call last):
  File "C:\Users\ustad\Desktop\arsaanalizvesunum\venv\lib\site-packages\flask\app.py", line 1513, in full_dispatch_request
    rv = self.dispatch_request()
  File "C:\Users\ustad\Desktop\arsaanalizvesunum\venv\lib\site-packages\flask\app.py", line 1499, in dispatch_request
    return self.ensure_sync(self.view_functions[rule.endpoint])(**req.view_args)
  File "C:\Users\ustad\Desktop\arsaanalizvesunum\venv\lib\site-packages\flask\app.py", line 518, in <lambda>
    view_func=lambda **kw: self_ref().send_static_file(**kw),  # type: ignore # noqa: B950
  File "C:\Users\ustad\Desktop\arsaanalizvesunum\venv\lib\site-packages\flask\scaffold.py", line 328, in send_static_file
    return send_from_directory(
  File "C:\Users\ustad\Desktop\arsaanalizvesunum\venv\lib\site-packages\flask\helpers.py", line 700, in send_from_directory
    return werkzeug.utils.send_from_directory(  # type: ignore
  File "C:\Users\ustad\Desktop\arsaanalizvesunum\venv\lib\site-packages\werkzeug\utils.py", line 841, in send_from_directory
    raise NotFound()
werkzeug.exceptions.NotFound: 404 Not Found: The requested URL was not found on the server. If you entered the URL manually please check your spelling and try again.

2025-05-15 01:41:18,033 - ERROR - app - Sunucu hatası oluştu: 404 Not Found: The requested URL was not found on the server. If you entered the URL manually please check your spelling and try again.
Traceback:
Traceback (most recent call last):
  File "C:\Users\ustad\Desktop\arsaanalizvesunum\venv\lib\site-packages\flask\app.py", line 1513, in full_dispatch_request
    rv = self.dispatch_request()
  File "C:\Users\ustad\Desktop\arsaanalizvesunum\venv\lib\site-packages\flask\app.py", line 1499, in dispatch_request
    return self.ensure_sync(self.view_functions[rule.endpoint])(**req.view_args)
  File "C:\Users\ustad\Desktop\arsaanalizvesunum\venv\lib\site-packages\flask\app.py", line 518, in <lambda>
    view_func=lambda **kw: self_ref().send_static_file(**kw),  # type: ignore # noqa: B950
  File "C:\Users\ustad\Desktop\arsaanalizvesunum\venv\lib\site-packages\flask\scaffold.py", line 328, in send_static_file
    return send_from_directory(
  File "C:\Users\ustad\Desktop\arsaanalizvesunum\venv\lib\site-packages\flask\helpers.py", line 700, in send_from_directory
    return werkzeug.utils.send_from_directory(  # type: ignore
  File "C:\Users\ustad\Desktop\arsaanalizvesunum\venv\lib\site-packages\werkzeug\utils.py", line 841, in send_from_directory
    raise NotFound()
werkzeug.exceptions.NotFound: 404 Not Found: The requested URL was not found on the server. If you entered the URL manually please check your spelling and try again.

2025-05-15 01:42:57,300 - ERROR - app - Sunucu hatası oluştu: 404 Not Found: The requested URL was not found on the server. If you entered the URL manually please check your spelling and try again.
Traceback:
Traceback (most recent call last):
  File "C:\Users\ustad\Desktop\arsaanalizvesunum\venv\lib\site-packages\flask\app.py", line 1513, in full_dispatch_request
    rv = self.dispatch_request()
  File "C:\Users\ustad\Desktop\arsaanalizvesunum\venv\lib\site-packages\flask\app.py", line 1489, in dispatch_request
    self.raise_routing_exception(req)
  File "C:\Users\ustad\Desktop\arsaanalizvesunum\venv\lib\site-packages\flask\app.py", line 1471, in raise_routing_exception
    raise request.routing_exception  # type: ignore
  File "C:\Users\ustad\Desktop\arsaanalizvesunum\venv\lib\site-packages\flask\ctx.py", line 367, in match_request
    result = self.url_adapter.match(return_rule=True)  # type: ignore
  File "C:\Users\ustad\Desktop\arsaanalizvesunum\venv\lib\site-packages\werkzeug\routing.py", line 2032, in match
    raise NotFound()
werkzeug.exceptions.NotFound: 404 Not Found: The requested URL was not found on the server. If you entered the URL manually please check your spelling and try again.

2025-05-15 01:42:58,730 - ERROR - app - Sunucu hatası oluştu: 404 Not Found: The requested URL was not found on the server. If you entered the URL manually please check your spelling and try again.
Traceback:
Traceback (most recent call last):
  File "C:\Users\ustad\Desktop\arsaanalizvesunum\venv\lib\site-packages\flask\app.py", line 1513, in full_dispatch_request
    rv = self.dispatch_request()
  File "C:\Users\ustad\Desktop\arsaanalizvesunum\venv\lib\site-packages\flask\app.py", line 1499, in dispatch_request
    return self.ensure_sync(self.view_functions[rule.endpoint])(**req.view_args)
  File "C:\Users\ustad\Desktop\arsaanalizvesunum\venv\lib\site-packages\flask\app.py", line 518, in <lambda>
    view_func=lambda **kw: self_ref().send_static_file(**kw),  # type: ignore # noqa: B950
  File "C:\Users\ustad\Desktop\arsaanalizvesunum\venv\lib\site-packages\flask\scaffold.py", line 328, in send_static_file
    return send_from_directory(
  File "C:\Users\ustad\Desktop\arsaanalizvesunum\venv\lib\site-packages\flask\helpers.py", line 700, in send_from_directory
    return werkzeug.utils.send_from_directory(  # type: ignore
  File "C:\Users\ustad\Desktop\arsaanalizvesunum\venv\lib\site-packages\werkzeug\utils.py", line 841, in send_from_directory
    raise NotFound()
werkzeug.exceptions.NotFound: 404 Not Found: The requested URL was not found on the server. If you entered the URL manually please check your spelling and try again.

2025-05-15 01:42:59,134 - ERROR - app - Sunucu hatası oluştu: 404 Not Found: The requested URL was not found on the server. If you entered the URL manually please check your spelling and try again.
Traceback:
Traceback (most recent call last):
  File "C:\Users\ustad\Desktop\arsaanalizvesunum\venv\lib\site-packages\flask\app.py", line 1513, in full_dispatch_request
    rv = self.dispatch_request()
  File "C:\Users\ustad\Desktop\arsaanalizvesunum\venv\lib\site-packages\flask\app.py", line 1499, in dispatch_request
    return self.ensure_sync(self.view_functions[rule.endpoint])(**req.view_args)
  File "C:\Users\ustad\Desktop\arsaanalizvesunum\venv\lib\site-packages\flask\app.py", line 518, in <lambda>
    view_func=lambda **kw: self_ref().send_static_file(**kw),  # type: ignore # noqa: B950
  File "C:\Users\ustad\Desktop\arsaanalizvesunum\venv\lib\site-packages\flask\scaffold.py", line 328, in send_static_file
    return send_from_directory(
  File "C:\Users\ustad\Desktop\arsaanalizvesunum\venv\lib\site-packages\flask\helpers.py", line 700, in send_from_directory
    return werkzeug.utils.send_from_directory(  # type: ignore
  File "C:\Users\ustad\Desktop\arsaanalizvesunum\venv\lib\site-packages\werkzeug\utils.py", line 841, in send_from_directory
    raise NotFound()
werkzeug.exceptions.NotFound: 404 Not Found: The requested URL was not found on the server. If you entered the URL manually please check your spelling and try again.

2025-05-15 01:46:27,312 - ERROR - app - Sunucu hatası oluştu: base.html
Traceback:
Traceback (most recent call last):
  File "C:\Users\ustad\Desktop\arsaanalizvesunum\venv\lib\site-packages\flask\app.py", line 1513, in full_dispatch_request
    rv = self.dispatch_request()
  File "C:\Users\ustad\Desktop\arsaanalizvesunum\venv\lib\site-packages\flask\app.py", line 1499, in dispatch_request
    return self.ensure_sync(self.view_functions[rule.endpoint])(**req.view_args)
  File "C:\Users\ustad\Desktop\arsaanalizvesunum\venv\lib\site-packages\flask_login\utils.py", line 290, in decorated_view
    return current_app.ensure_sync(func)(*args, **kwargs)
  File "c:\Users\ustad\Desktop\arsaanalizvesunum\blueprints\auth_decorators.py", line 15, in decorated_function
    return f(*args, **kwargs)
  File "c:\Users\ustad\Desktop\arsaanalizvesunum\blueprints\admin_bp.py", line 21, in dashboard
    return render_template('admin_dashboard.html', total_users=total_users, total_offices=total_offices)
  File "C:\Users\ustad\Desktop\arsaanalizvesunum\venv\lib\site-packages\flask\templating.py", line 147, in render_template
    return _render(
  File "C:\Users\ustad\Desktop\arsaanalizvesunum\venv\lib\site-packages\flask\templating.py", line 128, in _render
    rv = template.render(context)
  File "C:\Users\ustad\Desktop\arsaanalizvesunum\venv\lib\site-packages\jinja2\environment.py", line 1295, in render
    self.environment.handle_exception()
  File "C:\Users\ustad\Desktop\arsaanalizvesunum\venv\lib\site-packages\jinja2\environment.py", line 942, in handle_exception
    raise rewrite_traceback_stack(source=source)
  File "c:\Users\ustad\Desktop\arsaanalizvesunum\templates\admin\admin_dashboard.html", line 1, in top-level template code
    {% extends "base.html" %}
  File "C:\Users\ustad\Desktop\arsaanalizvesunum\venv\lib\site-packages\flask\templating.py", line 59, in get_source
    return self._get_source_fast(environment, template)
  File "C:\Users\ustad\Desktop\arsaanalizvesunum\venv\lib\site-packages\flask\templating.py", line 95, in _get_source_fast
    raise TemplateNotFound(template)
jinja2.exceptions.TemplateNotFound: base.html

2025-05-15 01:46:47,266 - ERROR - app - Sunucu hatası oluştu: 'toplam_acik_firsat_degeri_try' is undefined
Traceback:
Traceback (most recent call last):
  File "C:\Users\ustad\Desktop\arsaanalizvesunum\venv\lib\site-packages\flask\app.py", line 1513, in full_dispatch_request
    rv = self.dispatch_request()
  File "C:\Users\ustad\Desktop\arsaanalizvesunum\venv\lib\site-packages\flask\app.py", line 1499, in dispatch_request
    return self.ensure_sync(self.view_functions[rule.endpoint])(**req.view_args)
  File "C:\Users\ustad\Desktop\arsaanalizvesunum\venv\lib\site-packages\flask_login\utils.py", line 290, in decorated_view
    return current_app.ensure_sync(func)(*args, **kwargs)
  File "c:\Users\ustad\Desktop\arsaanalizvesunum\blueprints\auth_decorators.py", line 15, in decorated_function
    return f(*args, **kwargs)
  File "c:\Users\ustad\Desktop\arsaanalizvesunum\blueprints\admin_bp.py", line 21, in dashboard
    return render_template('admin_dashboard.html', total_users=total_users, total_offices=total_offices)
  File "C:\Users\ustad\Desktop\arsaanalizvesunum\venv\lib\site-packages\flask\templating.py", line 147, in render_template
    return _render(
  File "C:\Users\ustad\Desktop\arsaanalizvesunum\venv\lib\site-packages\flask\templating.py", line 128, in _render
    rv = template.render(context)
  File "C:\Users\ustad\Desktop\arsaanalizvesunum\venv\lib\site-packages\jinja2\environment.py", line 1295, in render
    self.environment.handle_exception()
  File "C:\Users\ustad\Desktop\arsaanalizvesunum\venv\lib\site-packages\jinja2\environment.py", line 942, in handle_exception
    raise rewrite_traceback_stack(source=source)
  File "c:\Users\ustad\Desktop\arsaanalizvesunum\templates\admin\admin_dashboard.html", line 1, in top-level template code
    {% extends "index.html" %}
  File "c:\Users\ustad\Desktop\arsaanalizvesunum\templates\index.html", line 697, in top-level template code
    {{ "%.0f"|format(toplam_acik_firsat_degeri_try) }} TL
  File "C:\Users\ustad\Desktop\arsaanalizvesunum\venv\lib\site-packages\jinja2\filters.py", line 1043, in do_format
    return soft_str(value) % (kwargs or args)
jinja2.exceptions.UndefinedError: 'toplam_acik_firsat_degeri_try' is undefined

2025-05-15 01:47:34,394 - ERROR - app - Sunucu hatası oluştu: 'toplam_acik_firsat_degeri_try' is undefined
Traceback:
Traceback (most recent call last):
  File "C:\Users\ustad\Desktop\arsaanalizvesunum\venv\lib\site-packages\flask\app.py", line 1513, in full_dispatch_request
    rv = self.dispatch_request()
  File "C:\Users\ustad\Desktop\arsaanalizvesunum\venv\lib\site-packages\flask\app.py", line 1499, in dispatch_request
    return self.ensure_sync(self.view_functions[rule.endpoint])(**req.view_args)
  File "C:\Users\ustad\Desktop\arsaanalizvesunum\venv\lib\site-packages\flask_login\utils.py", line 290, in decorated_view
    return current_app.ensure_sync(func)(*args, **kwargs)
  File "c:\Users\ustad\Desktop\arsaanalizvesunum\blueprints\auth_decorators.py", line 15, in decorated_function
    return f(*args, **kwargs)
  File "c:\Users\ustad\Desktop\arsaanalizvesunum\blueprints\admin_bp.py", line 21, in dashboard
    return render_template('admin_dashboard.html', total_users=total_users, total_offices=total_offices)
  File "C:\Users\ustad\Desktop\arsaanalizvesunum\venv\lib\site-packages\flask\templating.py", line 147, in render_template
    return _render(
  File "C:\Users\ustad\Desktop\arsaanalizvesunum\venv\lib\site-packages\flask\templating.py", line 128, in _render
    rv = template.render(context)
  File "C:\Users\ustad\Desktop\arsaanalizvesunum\venv\lib\site-packages\jinja2\environment.py", line 1295, in render
    self.environment.handle_exception()
  File "C:\Users\ustad\Desktop\arsaanalizvesunum\venv\lib\site-packages\jinja2\environment.py", line 942, in handle_exception
    raise rewrite_traceback_stack(source=source)
  File "c:\Users\ustad\Desktop\arsaanalizvesunum\templates\admin\admin_dashboard.html", line 1, in top-level template code
    {% extends "index.html" %}
  File "c:\Users\ustad\Desktop\arsaanalizvesunum\templates\index.html", line 697, in top-level template code
    {{ "%.0f"|format(toplam_acik_firsat_degeri_try) }} TL
  File "C:\Users\ustad\Desktop\arsaanalizvesunum\venv\lib\site-packages\jinja2\filters.py", line 1043, in do_format
    return soft_str(value) % (kwargs or args)
jinja2.exceptions.UndefinedError: 'toplam_acik_firsat_degeri_try' is undefined

2025-05-15 01:50:23,910 - ERROR - app - Sunucu hatası oluştu: 404 Not Found: The requested URL was not found on the server. If you entered the URL manually please check your spelling and try again.
Traceback:
Traceback (most recent call last):
  File "C:\Users\ustad\Desktop\arsaanalizvesunum\venv\lib\site-packages\flask\app.py", line 1513, in full_dispatch_request
    rv = self.dispatch_request()
  File "C:\Users\ustad\Desktop\arsaanalizvesunum\venv\lib\site-packages\flask\app.py", line 1499, in dispatch_request
    return self.ensure_sync(self.view_functions[rule.endpoint])(**req.view_args)
  File "C:\Users\ustad\Desktop\arsaanalizvesunum\venv\lib\site-packages\flask\app.py", line 518, in <lambda>
    view_func=lambda **kw: self_ref().send_static_file(**kw),  # type: ignore # noqa: B950
  File "C:\Users\ustad\Desktop\arsaanalizvesunum\venv\lib\site-packages\flask\scaffold.py", line 328, in send_static_file
    return send_from_directory(
  File "C:\Users\ustad\Desktop\arsaanalizvesunum\venv\lib\site-packages\flask\helpers.py", line 700, in send_from_directory
    return werkzeug.utils.send_from_directory(  # type: ignore
  File "C:\Users\ustad\Desktop\arsaanalizvesunum\venv\lib\site-packages\werkzeug\utils.py", line 841, in send_from_directory
    raise NotFound()
werkzeug.exceptions.NotFound: 404 Not Found: The requested URL was not found on the server. If you entered the URL manually please check your spelling and try again.

2025-05-15 01:54:37,289 - INFO - app - Flask uygulaması başarıyla oluşturuldu ve yapılandırıldı.
2025-05-15 01:54:38,993 - ERROR - app - Sunucu hatası oluştu: _messages.html
Traceback:
Traceback (most recent call last):
  File "C:\Users\ustad\Desktop\arsaanalizvesunum\venv\lib\site-packages\flask\app.py", line 1513, in full_dispatch_request
    rv = self.dispatch_request()
  File "C:\Users\ustad\Desktop\arsaanalizvesunum\venv\lib\site-packages\flask\app.py", line 1499, in dispatch_request
    return self.ensure_sync(self.view_functions[rule.endpoint])(**req.view_args)
  File "C:\Users\ustad\Desktop\arsaanalizvesunum\venv\lib\site-packages\flask_login\utils.py", line 290, in decorated_view
    return current_app.ensure_sync(func)(*args, **kwargs)
  File "c:\Users\ustad\Desktop\arsaanalizvesunum\blueprints\auth_decorators.py", line 15, in decorated_function
    return f(*args, **kwargs)
  File "c:\Users\ustad\Desktop\arsaanalizvesunum\blueprints\admin_bp.py", line 23, in dashboard
    return render_template('admin_dashboard.html', total_users=total_users, total_offices=total_offices)
  File "C:\Users\ustad\Desktop\arsaanalizvesunum\venv\lib\site-packages\flask\templating.py", line 147, in render_template
    return _render(
  File "C:\Users\ustad\Desktop\arsaanalizvesunum\venv\lib\site-packages\flask\templating.py", line 128, in _render
    rv = template.render(context)
  File "C:\Users\ustad\Desktop\arsaanalizvesunum\venv\lib\site-packages\jinja2\environment.py", line 1295, in render
    self.environment.handle_exception()
  File "C:\Users\ustad\Desktop\arsaanalizvesunum\venv\lib\site-packages\jinja2\environment.py", line 942, in handle_exception
    raise rewrite_traceback_stack(source=source)
  File "c:\Users\ustad\Desktop\arsaanalizvesunum\templates\admin\admin_dashboard.html", line 1, in top-level template code
    {% extends "base_admin.html" %} {# VEYA genel base.html'iniz #}
  File "c:\Users\ustad\Desktop\arsaanalizvesunum\templates\admin\base_admin.html", line 33, in top-level template code
    {% block content %}{% endblock %}
  File "c:\Users\ustad\Desktop\arsaanalizvesunum\templates\admin\admin_dashboard.html", line 14, in block 'content'
    {% include "_messages.html" %}
  File "C:\Users\ustad\Desktop\arsaanalizvesunum\venv\lib\site-packages\flask\templating.py", line 59, in get_source
    return self._get_source_fast(environment, template)
  File "C:\Users\ustad\Desktop\arsaanalizvesunum\venv\lib\site-packages\flask\templating.py", line 95, in _get_source_fast
    raise TemplateNotFound(template)
jinja2.exceptions.TemplateNotFound: _messages.html

2025-05-15 01:54:45,068 - ERROR - app - Sunucu hatası oluştu: _messages.html
Traceback:
Traceback (most recent call last):
  File "C:\Users\ustad\Desktop\arsaanalizvesunum\venv\lib\site-packages\flask\app.py", line 1513, in full_dispatch_request
    rv = self.dispatch_request()
  File "C:\Users\ustad\Desktop\arsaanalizvesunum\venv\lib\site-packages\flask\app.py", line 1499, in dispatch_request
    return self.ensure_sync(self.view_functions[rule.endpoint])(**req.view_args)
  File "C:\Users\ustad\Desktop\arsaanalizvesunum\venv\lib\site-packages\flask_login\utils.py", line 290, in decorated_view
    return current_app.ensure_sync(func)(*args, **kwargs)
  File "c:\Users\ustad\Desktop\arsaanalizvesunum\blueprints\auth_decorators.py", line 15, in decorated_function
    return f(*args, **kwargs)
  File "c:\Users\ustad\Desktop\arsaanalizvesunum\blueprints\admin_bp.py", line 23, in dashboard
    return render_template('admin_dashboard.html', total_users=total_users, total_offices=total_offices)
  File "C:\Users\ustad\Desktop\arsaanalizvesunum\venv\lib\site-packages\flask\templating.py", line 147, in render_template
    return _render(
  File "C:\Users\ustad\Desktop\arsaanalizvesunum\venv\lib\site-packages\flask\templating.py", line 128, in _render
    rv = template.render(context)
  File "C:\Users\ustad\Desktop\arsaanalizvesunum\venv\lib\site-packages\jinja2\environment.py", line 1295, in render
    self.environment.handle_exception()
  File "C:\Users\ustad\Desktop\arsaanalizvesunum\venv\lib\site-packages\jinja2\environment.py", line 942, in handle_exception
    raise rewrite_traceback_stack(source=source)
  File "c:\Users\ustad\Desktop\arsaanalizvesunum\templates\admin\admin_dashboard.html", line 1, in top-level template code
    {% extends "base_admin.html" %} {# VEYA genel base.html'iniz #}
  File "c:\Users\ustad\Desktop\arsaanalizvesunum\templates\admin\base_admin.html", line 33, in top-level template code
    {% block content %}{% endblock %}
  File "c:\Users\ustad\Desktop\arsaanalizvesunum\templates\admin\admin_dashboard.html", line 14, in block 'content'
    {% include "_messages.html" %}
  File "C:\Users\ustad\Desktop\arsaanalizvesunum\venv\lib\site-packages\flask\templating.py", line 59, in get_source
    return self._get_source_fast(environment, template)
  File "C:\Users\ustad\Desktop\arsaanalizvesunum\venv\lib\site-packages\flask\templating.py", line 95, in _get_source_fast
    raise TemplateNotFound(template)
jinja2.exceptions.TemplateNotFound: _messages.html

2025-05-15 01:55:07,409 - ERROR - app - Sunucu hatası oluştu: 404 Not Found: The requested URL was not found on the server. If you entered the URL manually please check your spelling and try again.
Traceback:
Traceback (most recent call last):
  File "C:\Users\ustad\Desktop\arsaanalizvesunum\venv\lib\site-packages\flask\app.py", line 1513, in full_dispatch_request
    rv = self.dispatch_request()
  File "C:\Users\ustad\Desktop\arsaanalizvesunum\venv\lib\site-packages\flask\app.py", line 1499, in dispatch_request
    return self.ensure_sync(self.view_functions[rule.endpoint])(**req.view_args)
  File "C:\Users\ustad\Desktop\arsaanalizvesunum\venv\lib\site-packages\flask\app.py", line 518, in <lambda>
    view_func=lambda **kw: self_ref().send_static_file(**kw),  # type: ignore # noqa: B950
  File "C:\Users\ustad\Desktop\arsaanalizvesunum\venv\lib\site-packages\flask\scaffold.py", line 328, in send_static_file
    return send_from_directory(
  File "C:\Users\ustad\Desktop\arsaanalizvesunum\venv\lib\site-packages\flask\helpers.py", line 700, in send_from_directory
    return werkzeug.utils.send_from_directory(  # type: ignore
  File "C:\Users\ustad\Desktop\arsaanalizvesunum\venv\lib\site-packages\werkzeug\utils.py", line 841, in send_from_directory
    raise NotFound()
werkzeug.exceptions.NotFound: 404 Not Found: The requested URL was not found on the server. If you entered the URL manually please check your spelling and try again.

2025-05-15 01:55:15,959 - ERROR - app - Sunucu hatası oluştu: 'toplam_acik_firsat_degeri_try' is undefined
Traceback:
Traceback (most recent call last):
  File "C:\Users\ustad\Desktop\arsaanalizvesunum\venv\lib\site-packages\flask\app.py", line 1513, in full_dispatch_request
    rv = self.dispatch_request()
  File "C:\Users\ustad\Desktop\arsaanalizvesunum\venv\lib\site-packages\flask\app.py", line 1499, in dispatch_request
    return self.ensure_sync(self.view_functions[rule.endpoint])(**req.view_args)
  File "C:\Users\ustad\Desktop\arsaanalizvesunum\venv\lib\site-packages\flask_login\utils.py", line 290, in decorated_view
    return current_app.ensure_sync(func)(*args, **kwargs)
  File "c:\Users\ustad\Desktop\arsaanalizvesunum\blueprints\auth_decorators.py", line 15, in decorated_function
    return f(*args, **kwargs)
  File "c:\Users\ustad\Desktop\arsaanalizvesunum\blueprints\admin_bp.py", line 38, in create_office
    return render_template('create_office.html')
  File "C:\Users\ustad\Desktop\arsaanalizvesunum\venv\lib\site-packages\flask\templating.py", line 147, in render_template
    return _render(
  File "C:\Users\ustad\Desktop\arsaanalizvesunum\venv\lib\site-packages\flask\templating.py", line 128, in _render
    rv = template.render(context)
  File "C:\Users\ustad\Desktop\arsaanalizvesunum\venv\lib\site-packages\jinja2\environment.py", line 1295, in render
    self.environment.handle_exception()
  File "C:\Users\ustad\Desktop\arsaanalizvesunum\venv\lib\site-packages\jinja2\environment.py", line 942, in handle_exception
    raise rewrite_traceback_stack(source=source)
  File "c:\Users\ustad\Desktop\arsaanalizvesunum\templates\admin\create_office.html", line 1, in top-level template code
    {% extends "index.html" %}
  File "c:\Users\ustad\Desktop\arsaanalizvesunum\templates\index.html", line 697, in top-level template code
    {{ "%.0f"|format(toplam_acik_firsat_degeri_try) }} TL
  File "C:\Users\ustad\Desktop\arsaanalizvesunum\venv\lib\site-packages\jinja2\filters.py", line 1043, in do_format
    return soft_str(value) % (kwargs or args)
jinja2.exceptions.UndefinedError: 'toplam_acik_firsat_degeri_try' is undefined

2025-05-15 01:59:59,331 - INFO - app - Flask uygulaması başarıyla oluşturuldu ve yapılandırıldı.
2025-05-15 02:00:00,423 - ERROR - app - Sunucu hatası oluştu: 'toplam_acik_firsat_degeri_try' is undefined
Traceback:
Traceback (most recent call last):
  File "C:\Users\ustad\Desktop\arsaanalizvesunum\venv\lib\site-packages\flask\app.py", line 1513, in full_dispatch_request
    rv = self.dispatch_request()
  File "C:\Users\ustad\Desktop\arsaanalizvesunum\venv\lib\site-packages\flask\app.py", line 1499, in dispatch_request
    return self.ensure_sync(self.view_functions[rule.endpoint])(**req.view_args)
  File "C:\Users\ustad\Desktop\arsaanalizvesunum\venv\lib\site-packages\flask_login\utils.py", line 290, in decorated_view
    return current_app.ensure_sync(func)(*args, **kwargs)
  File "c:\Users\ustad\Desktop\arsaanalizvesunum\blueprints\auth_decorators.py", line 15, in decorated_function
    return f(*args, **kwargs)
  File "c:\Users\ustad\Desktop\arsaanalizvesunum\blueprints\admin_bp.py", line 58, in create_office
    return render_template('create_office.html')
  File "C:\Users\ustad\Desktop\arsaanalizvesunum\venv\lib\site-packages\flask\templating.py", line 147, in render_template
    return _render(
  File "C:\Users\ustad\Desktop\arsaanalizvesunum\venv\lib\site-packages\flask\templating.py", line 128, in _render
    rv = template.render(context)
  File "C:\Users\ustad\Desktop\arsaanalizvesunum\venv\lib\site-packages\jinja2\environment.py", line 1295, in render
    self.environment.handle_exception()
  File "C:\Users\ustad\Desktop\arsaanalizvesunum\venv\lib\site-packages\jinja2\environment.py", line 942, in handle_exception
    raise rewrite_traceback_stack(source=source)
  File "c:\Users\ustad\Desktop\arsaanalizvesunum\templates\admin\create_office.html", line 1, in top-level template code
    {% extends "index.html" %}
  File "c:\Users\ustad\Desktop\arsaanalizvesunum\templates\index.html", line 697, in top-level template code
    {{ "%.0f"|format(toplam_acik_firsat_degeri_try) }} TL
  File "C:\Users\ustad\Desktop\arsaanalizvesunum\venv\lib\site-packages\jinja2\filters.py", line 1043, in do_format
    return soft_str(value) % (kwargs or args)
jinja2.exceptions.UndefinedError: 'toplam_acik_firsat_degeri_try' is undefined

2025-05-15 02:00:04,454 - ERROR - app - Sunucu hatası oluştu: type object 'User' has no attribute 'created_at'
Traceback:
Traceback (most recent call last):
  File "C:\Users\ustad\Desktop\arsaanalizvesunum\venv\lib\site-packages\flask\app.py", line 1513, in full_dispatch_request
    rv = self.dispatch_request()
  File "C:\Users\ustad\Desktop\arsaanalizvesunum\venv\lib\site-packages\flask\app.py", line 1499, in dispatch_request
    return self.ensure_sync(self.view_functions[rule.endpoint])(**req.view_args)
  File "C:\Users\ustad\Desktop\arsaanalizvesunum\venv\lib\site-packages\flask_login\utils.py", line 290, in decorated_view
    return current_app.ensure_sync(func)(*args, **kwargs)
  File "c:\Users\ustad\Desktop\arsaanalizvesunum\blueprints\auth_decorators.py", line 15, in decorated_function
    return f(*args, **kwargs)
  File "c:\Users\ustad\Desktop\arsaanalizvesunum\blueprints\admin_bp.py", line 25, in dashboard
    recent_brokers = User.query.filter_by(role='broker').order_by(User.created_at.desc()).limit(5).all()
AttributeError: type object 'User' has no attribute 'created_at'

2025-05-15 02:01:24,745 - INFO - app - Flask uygulaması başarıyla oluşturuldu ve yapılandırıldı.
2025-05-15 02:01:25,946 - ERROR - app - Sunucu hatası oluştu: type object 'User' has no attribute 'created_at'
Traceback:
Traceback (most recent call last):
  File "C:\Users\ustad\Desktop\arsaanalizvesunum\venv\lib\site-packages\flask\app.py", line 1513, in full_dispatch_request
    rv = self.dispatch_request()
  File "C:\Users\ustad\Desktop\arsaanalizvesunum\venv\lib\site-packages\flask\app.py", line 1499, in dispatch_request
    return self.ensure_sync(self.view_functions[rule.endpoint])(**req.view_args)
  File "C:\Users\ustad\Desktop\arsaanalizvesunum\venv\lib\site-packages\flask_login\utils.py", line 290, in decorated_view
    return current_app.ensure_sync(func)(*args, **kwargs)
  File "c:\Users\ustad\Desktop\arsaanalizvesunum\blueprints\auth_decorators.py", line 15, in decorated_function
    return f(*args, **kwargs)
  File "c:\Users\ustad\Desktop\arsaanalizvesunum\blueprints\admin_bp.py", line 25, in dashboard
    recent_brokers = User.query.filter_by(role='broker').order_by(User.created_at.desc()).limit(5).all()
AttributeError: type object 'User' has no attribute 'created_at'

2025-05-15 02:03:49,346 - INFO - app - Flask uygulaması başarıyla oluşturuldu ve yapılandırıldı.
2025-05-15 02:03:51,170 - ERROR - app - Sunucu hatası oluştu: type object 'User' has no attribute 'created_at'
Traceback:
Traceback (most recent call last):
  File "C:\Users\ustad\Desktop\arsaanalizvesunum\venv\lib\site-packages\flask\app.py", line 1513, in full_dispatch_request
    rv = self.dispatch_request()
  File "C:\Users\ustad\Desktop\arsaanalizvesunum\venv\lib\site-packages\flask\app.py", line 1499, in dispatch_request
    return self.ensure_sync(self.view_functions[rule.endpoint])(**req.view_args)
  File "C:\Users\ustad\Desktop\arsaanalizvesunum\venv\lib\site-packages\flask_login\utils.py", line 290, in decorated_view
    return current_app.ensure_sync(func)(*args, **kwargs)
  File "c:\Users\ustad\Desktop\arsaanalizvesunum\blueprints\auth_decorators.py", line 15, in decorated_function
    return f(*args, **kwargs)
  File "c:\Users\ustad\Desktop\arsaanalizvesunum\blueprints\admin_bp.py", line 26, in dashboard
    recent_consultants = User.query.filter_by(role='consultant').order_by(User.created_at.desc()).limit(5).all()
AttributeError: type object 'User' has no attribute 'created_at'

2025-05-15 02:04:19,588 - INFO - app - Flask uygulaması başarıyla oluşturuldu ve yapılandırıldı.
2025-05-15 02:04:20,914 - ERROR - app - Sunucu hatası oluştu: type object 'Deal' has no attribute 'company_name'
Traceback:
Traceback (most recent call last):
  File "C:\Users\ustad\Desktop\arsaanalizvesunum\venv\lib\site-packages\flask\app.py", line 1513, in full_dispatch_request
    rv = self.dispatch_request()
  File "C:\Users\ustad\Desktop\arsaanalizvesunum\venv\lib\site-packages\flask\app.py", line 1499, in dispatch_request
    return self.ensure_sync(self.view_functions[rule.endpoint])(**req.view_args)
  File "C:\Users\ustad\Desktop\arsaanalizvesunum\venv\lib\site-packages\flask_login\utils.py", line 290, in decorated_view
    return current_app.ensure_sync(func)(*args, **kwargs)
  File "c:\Users\ustad\Desktop\arsaanalizvesunum\blueprints\auth_decorators.py", line 15, in decorated_function
    return f(*args, **kwargs)
  File "c:\Users\ustad\Desktop\arsaanalizvesunum\blueprints\admin_bp.py", line 26, in dashboard
    total_companies = Deal.query.distinct(Deal.company_name).count()
AttributeError: type object 'Deal' has no attribute 'company_name'

2025-05-15 02:04:47,902 - INFO - app - Flask uygulaması başarıyla oluşturuldu ve yapılandırıldı.
2025-05-15 02:04:49,720 - ERROR - app - Sunucu hatası oluştu: 404 Not Found: The requested URL was not found on the server. If you entered the URL manually please check your spelling and try again.
Traceback:
Traceback (most recent call last):
  File "C:\Users\ustad\Desktop\arsaanalizvesunum\venv\lib\site-packages\flask\app.py", line 1513, in full_dispatch_request
    rv = self.dispatch_request()
  File "C:\Users\ustad\Desktop\arsaanalizvesunum\venv\lib\site-packages\flask\app.py", line 1499, in dispatch_request
    return self.ensure_sync(self.view_functions[rule.endpoint])(**req.view_args)
  File "C:\Users\ustad\Desktop\arsaanalizvesunum\venv\lib\site-packages\flask\app.py", line 518, in <lambda>
    view_func=lambda **kw: self_ref().send_static_file(**kw),  # type: ignore # noqa: B950
  File "C:\Users\ustad\Desktop\arsaanalizvesunum\venv\lib\site-packages\flask\scaffold.py", line 328, in send_static_file
    return send_from_directory(
  File "C:\Users\ustad\Desktop\arsaanalizvesunum\venv\lib\site-packages\flask\helpers.py", line 700, in send_from_directory
    return werkzeug.utils.send_from_directory(  # type: ignore
  File "C:\Users\ustad\Desktop\arsaanalizvesunum\venv\lib\site-packages\werkzeug\utils.py", line 841, in send_from_directory
    raise NotFound()
werkzeug.exceptions.NotFound: 404 Not Found: The requested URL was not found on the server. If you entered the URL manually please check your spelling and try again.

2025-05-15 02:05:00,294 - ERROR - app - Sunucu hatası oluştu: 404 Not Found: The requested URL was not found on the server. If you entered the URL manually please check your spelling and try again.
Traceback:
Traceback (most recent call last):
  File "C:\Users\ustad\Desktop\arsaanalizvesunum\venv\lib\site-packages\flask\app.py", line 1513, in full_dispatch_request
    rv = self.dispatch_request()
  File "C:\Users\ustad\Desktop\arsaanalizvesunum\venv\lib\site-packages\flask\app.py", line 1499, in dispatch_request
    return self.ensure_sync(self.view_functions[rule.endpoint])(**req.view_args)
  File "C:\Users\ustad\Desktop\arsaanalizvesunum\venv\lib\site-packages\flask\app.py", line 518, in <lambda>
    view_func=lambda **kw: self_ref().send_static_file(**kw),  # type: ignore # noqa: B950
  File "C:\Users\ustad\Desktop\arsaanalizvesunum\venv\lib\site-packages\flask\scaffold.py", line 328, in send_static_file
    return send_from_directory(
  File "C:\Users\ustad\Desktop\arsaanalizvesunum\venv\lib\site-packages\flask\helpers.py", line 700, in send_from_directory
    return werkzeug.utils.send_from_directory(  # type: ignore
  File "C:\Users\ustad\Desktop\arsaanalizvesunum\venv\lib\site-packages\werkzeug\utils.py", line 841, in send_from_directory
    raise NotFound()
werkzeug.exceptions.NotFound: 404 Not Found: The requested URL was not found on the server. If you entered the URL manually please check your spelling and try again.

2025-05-15 02:05:01,919 - ERROR - app - Sunucu hatası oluştu: 'toplam_acik_firsat_degeri_try' is undefined
Traceback:
Traceback (most recent call last):
  File "C:\Users\ustad\Desktop\arsaanalizvesunum\venv\lib\site-packages\flask\app.py", line 1513, in full_dispatch_request
    rv = self.dispatch_request()
  File "C:\Users\ustad\Desktop\arsaanalizvesunum\venv\lib\site-packages\flask\app.py", line 1499, in dispatch_request
    return self.ensure_sync(self.view_functions[rule.endpoint])(**req.view_args)
  File "C:\Users\ustad\Desktop\arsaanalizvesunum\venv\lib\site-packages\flask_login\utils.py", line 290, in decorated_view
    return current_app.ensure_sync(func)(*args, **kwargs)
  File "c:\Users\ustad\Desktop\arsaanalizvesunum\blueprints\auth_decorators.py", line 15, in decorated_function
    return f(*args, **kwargs)
  File "c:\Users\ustad\Desktop\arsaanalizvesunum\blueprints\admin_bp.py", line 53, in create_office
    return render_template('create_office.html')
  File "C:\Users\ustad\Desktop\arsaanalizvesunum\venv\lib\site-packages\flask\templating.py", line 147, in render_template
    return _render(
  File "C:\Users\ustad\Desktop\arsaanalizvesunum\venv\lib\site-packages\flask\templating.py", line 128, in _render
    rv = template.render(context)
  File "C:\Users\ustad\Desktop\arsaanalizvesunum\venv\lib\site-packages\jinja2\environment.py", line 1295, in render
    self.environment.handle_exception()
  File "C:\Users\ustad\Desktop\arsaanalizvesunum\venv\lib\site-packages\jinja2\environment.py", line 942, in handle_exception
    raise rewrite_traceback_stack(source=source)
  File "c:\Users\ustad\Desktop\arsaanalizvesunum\templates\admin\create_office.html", line 1, in top-level template code
    {% extends "index.html" %}
  File "c:\Users\ustad\Desktop\arsaanalizvesunum\templates\index.html", line 697, in top-level template code
    {{ "%.0f"|format(toplam_acik_firsat_degeri_try) }} TL
  File "C:\Users\ustad\Desktop\arsaanalizvesunum\venv\lib\site-packages\jinja2\filters.py", line 1043, in do_format
    return soft_str(value) % (kwargs or args)
jinja2.exceptions.UndefinedError: 'toplam_acik_firsat_degeri_try' is undefined

2025-05-15 02:07:13,331 - INFO - app - Flask uygulaması başarıyla oluşturuldu ve yapılandırıldı.
2025-05-15 02:07:14,875 - ERROR - app - Sunucu hatası oluştu: 404 Not Found: The requested URL was not found on the server. If you entered the URL manually please check your spelling and try again.
Traceback:
Traceback (most recent call last):
  File "C:\Users\ustad\Desktop\arsaanalizvesunum\venv\lib\site-packages\flask\app.py", line 1513, in full_dispatch_request
    rv = self.dispatch_request()
  File "C:\Users\ustad\Desktop\arsaanalizvesunum\venv\lib\site-packages\flask\app.py", line 1499, in dispatch_request
    return self.ensure_sync(self.view_functions[rule.endpoint])(**req.view_args)
  File "C:\Users\ustad\Desktop\arsaanalizvesunum\venv\lib\site-packages\flask\app.py", line 518, in <lambda>
    view_func=lambda **kw: self_ref().send_static_file(**kw),  # type: ignore # noqa: B950
  File "C:\Users\ustad\Desktop\arsaanalizvesunum\venv\lib\site-packages\flask\scaffold.py", line 328, in send_static_file
    return send_from_directory(
  File "C:\Users\ustad\Desktop\arsaanalizvesunum\venv\lib\site-packages\flask\helpers.py", line 700, in send_from_directory
    return werkzeug.utils.send_from_directory(  # type: ignore
  File "C:\Users\ustad\Desktop\arsaanalizvesunum\venv\lib\site-packages\werkzeug\utils.py", line 841, in send_from_directory
    raise NotFound()
werkzeug.exceptions.NotFound: 404 Not Found: The requested URL was not found on the server. If you entered the URL manually please check your spelling and try again.

2025-05-15 02:07:34,519 - ERROR - app - Sunucu hatası oluştu: 404 Not Found: The requested URL was not found on the server. If you entered the URL manually please check your spelling and try again.
Traceback:
Traceback (most recent call last):
  File "C:\Users\ustad\Desktop\arsaanalizvesunum\venv\lib\site-packages\flask\app.py", line 1513, in full_dispatch_request
    rv = self.dispatch_request()
  File "C:\Users\ustad\Desktop\arsaanalizvesunum\venv\lib\site-packages\flask\app.py", line 1499, in dispatch_request
    return self.ensure_sync(self.view_functions[rule.endpoint])(**req.view_args)
  File "C:\Users\ustad\Desktop\arsaanalizvesunum\venv\lib\site-packages\flask\app.py", line 518, in <lambda>
    view_func=lambda **kw: self_ref().send_static_file(**kw),  # type: ignore # noqa: B950
  File "C:\Users\ustad\Desktop\arsaanalizvesunum\venv\lib\site-packages\flask\scaffold.py", line 328, in send_static_file
    return send_from_directory(
  File "C:\Users\ustad\Desktop\arsaanalizvesunum\venv\lib\site-packages\flask\helpers.py", line 700, in send_from_directory
    return werkzeug.utils.send_from_directory(  # type: ignore
  File "C:\Users\ustad\Desktop\arsaanalizvesunum\venv\lib\site-packages\werkzeug\utils.py", line 841, in send_from_directory
    raise NotFound()
werkzeug.exceptions.NotFound: 404 Not Found: The requested URL was not found on the server. If you entered the URL manually please check your spelling and try again.

2025-05-15 02:09:00,305 - ERROR - app - Sunucu hatası oluştu: 404 Not Found: The requested URL was not found on the server. If you entered the URL manually please check your spelling and try again.
Traceback:
Traceback (most recent call last):
  File "C:\Users\ustad\Desktop\arsaanalizvesunum\venv\lib\site-packages\flask\app.py", line 1513, in full_dispatch_request
    rv = self.dispatch_request()
  File "C:\Users\ustad\Desktop\arsaanalizvesunum\venv\lib\site-packages\flask\app.py", line 1499, in dispatch_request
    return self.ensure_sync(self.view_functions[rule.endpoint])(**req.view_args)
  File "C:\Users\ustad\Desktop\arsaanalizvesunum\venv\lib\site-packages\flask\app.py", line 518, in <lambda>
    view_func=lambda **kw: self_ref().send_static_file(**kw),  # type: ignore # noqa: B950
  File "C:\Users\ustad\Desktop\arsaanalizvesunum\venv\lib\site-packages\flask\scaffold.py", line 328, in send_static_file
    return send_from_directory(
  File "C:\Users\ustad\Desktop\arsaanalizvesunum\venv\lib\site-packages\flask\helpers.py", line 700, in send_from_directory
    return werkzeug.utils.send_from_directory(  # type: ignore
  File "C:\Users\ustad\Desktop\arsaanalizvesunum\venv\lib\site-packages\werkzeug\utils.py", line 841, in send_from_directory
    raise NotFound()
werkzeug.exceptions.NotFound: 404 Not Found: The requested URL was not found on the server. If you entered the URL manually please check your spelling and try again.

2025-05-15 02:09:02,637 - ERROR - app - Sunucu hatası oluştu: 404 Not Found: The requested URL was not found on the server. If you entered the URL manually please check your spelling and try again.
Traceback:
Traceback (most recent call last):
  File "C:\Users\ustad\Desktop\arsaanalizvesunum\venv\lib\site-packages\flask\app.py", line 1513, in full_dispatch_request
    rv = self.dispatch_request()
  File "C:\Users\ustad\Desktop\arsaanalizvesunum\venv\lib\site-packages\flask\app.py", line 1499, in dispatch_request
    return self.ensure_sync(self.view_functions[rule.endpoint])(**req.view_args)
  File "C:\Users\ustad\Desktop\arsaanalizvesunum\venv\lib\site-packages\flask\app.py", line 518, in <lambda>
    view_func=lambda **kw: self_ref().send_static_file(**kw),  # type: ignore # noqa: B950
  File "C:\Users\ustad\Desktop\arsaanalizvesunum\venv\lib\site-packages\flask\scaffold.py", line 328, in send_static_file
    return send_from_directory(
  File "C:\Users\ustad\Desktop\arsaanalizvesunum\venv\lib\site-packages\flask\helpers.py", line 700, in send_from_directory
    return werkzeug.utils.send_from_directory(  # type: ignore
  File "C:\Users\ustad\Desktop\arsaanalizvesunum\venv\lib\site-packages\werkzeug\utils.py", line 841, in send_from_directory
    raise NotFound()
werkzeug.exceptions.NotFound: 404 Not Found: The requested URL was not found on the server. If you entered the URL manually please check your spelling and try again.

2025-05-15 02:09:22,784 - ERROR - app - Sunucu hatası oluştu: (pyodbc.OperationalError) ('08S01', '[08S01] [Microsoft][ODBC Driver 18 for SQL Server]TCP Sağlayıcısı: Bağlanılan uygun olarak belli bir süre içinde yanıt vermediğinden veya kurulan\r\nbağlantı bağlanılan ana bilgisayar yanıt vermediğinden bir bağlantı kurulamadı.\r\n (10060) (SQLExecDirectW); [08S01] [Microsoft][ODBC Driver 18 for SQL Server]İletişim bağlantısı hatası (10060)')
[SQL: SELECT users.id AS users_id, users.email AS users_email, users.password_hash AS users_password_hash, users.registered_on AS users_registered_on, users.ad AS users_ad, users.soyad AS users_soyad, users.telefon AS users_telefon, users.firma AS users_firma, users.unvan AS users_unvan, users.adres AS users_adres, users.profil_foto AS users_profil_foto, users.is_active AS users_is_active, users.son_giris AS users_son_giris, users.failed_attempts AS users_failed_attempts, users.reset_token AS users_reset_token, users.reset_token_expires AS users_reset_token_expires, users.timezone AS users_timezone, users.role AS users_role, users.office_id AS users_office_id, users.reports_to_user_id AS users_reports_to_user_id 
FROM users 
WHERE users.id = ?]
[parameters: (4,)]
(Background on this error at: https://sqlalche.me/e/14/e3q8)
Traceback:
Traceback (most recent call last):
  File "C:\Users\ustad\Desktop\arsaanalizvesunum\venv\lib\site-packages\sqlalchemy\engine\base.py", line 1910, in _execute_context
    self.dialect.do_execute(
  File "C:\Users\ustad\Desktop\arsaanalizvesunum\venv\lib\site-packages\sqlalchemy\engine\default.py", line 736, in do_execute
    cursor.execute(statement, parameters)
pyodbc.OperationalError: ('08S01', '[08S01] [Microsoft][ODBC Driver 18 for SQL Server]TCP Sağlayıcısı: Bağlanılan uygun olarak belli bir süre içinde yanıt vermediğinden veya kurulan\r\nbağlantı bağlanılan ana bilgisayar yanıt vermediğinden bir bağlantı kurulamadı.\r\n (10060) (SQLExecDirectW); [08S01] [Microsoft][ODBC Driver 18 for SQL Server]İletişim bağlantısı hatası (10060)')

The above exception was the direct cause of the following exception:

Traceback (most recent call last):
  File "C:\Users\ustad\Desktop\arsaanalizvesunum\venv\lib\site-packages\flask\app.py", line 1513, in full_dispatch_request
    rv = self.dispatch_request()
  File "C:\Users\ustad\Desktop\arsaanalizvesunum\venv\lib\site-packages\flask\app.py", line 1499, in dispatch_request
    return self.ensure_sync(self.view_functions[rule.endpoint])(**req.view_args)
  File "C:\Users\ustad\Desktop\arsaanalizvesunum\venv\lib\site-packages\flask_login\utils.py", line 284, in decorated_view
    elif not current_user.is_authenticated:
  File "C:\Users\ustad\Desktop\arsaanalizvesunum\venv\lib\site-packages\werkzeug\local.py", line 422, in __get__
    obj = instance._get_current_object()
  File "C:\Users\ustad\Desktop\arsaanalizvesunum\venv\lib\site-packages\werkzeug\local.py", line 544, in _get_current_object
    return self.__local()  # type: ignore
  File "C:\Users\ustad\Desktop\arsaanalizvesunum\venv\lib\site-packages\flask_login\utils.py", line 25, in <lambda>
    current_user = LocalProxy(lambda: _get_user())
  File "C:\Users\ustad\Desktop\arsaanalizvesunum\venv\lib\site-packages\flask_login\utils.py", line 370, in _get_user
    current_app.login_manager._load_user()
  File "C:\Users\ustad\Desktop\arsaanalizvesunum\venv\lib\site-packages\flask_login\login_manager.py", line 364, in _load_user
    user = self._user_callback(user_id)
  File "c:\Users\ustad\Desktop\arsaanalizvesunum\app.py", line 79, in load_user
    return User.query.get(int(user_id))
  File "<string>", line 2, in get
  File "C:\Users\ustad\Desktop\arsaanalizvesunum\venv\lib\site-packages\sqlalchemy\util\deprecations.py", line 468, in warned
    return fn(*args, **kwargs)
  File "C:\Users\ustad\Desktop\arsaanalizvesunum\venv\lib\site-packages\sqlalchemy\orm\query.py", line 947, in get
    return self._get_impl(ident, loading.load_on_pk_identity)
  File "C:\Users\ustad\Desktop\arsaanalizvesunum\venv\lib\site-packages\sqlalchemy\orm\query.py", line 951, in _get_impl
    return self.session._get_impl(
  File "C:\Users\ustad\Desktop\arsaanalizvesunum\venv\lib\site-packages\sqlalchemy\orm\session.py", line 2975, in _get_impl
    return db_load_fn(
  File "C:\Users\ustad\Desktop\arsaanalizvesunum\venv\lib\site-packages\sqlalchemy\orm\loading.py", line 530, in load_on_pk_identity
    session.execute(
  File "C:\Users\ustad\Desktop\arsaanalizvesunum\venv\lib\site-packages\sqlalchemy\orm\session.py", line 1717, in execute
    result = conn._execute_20(statement, params or {}, execution_options)
  File "C:\Users\ustad\Desktop\arsaanalizvesunum\venv\lib\site-packages\sqlalchemy\engine\base.py", line 1710, in _execute_20
    return meth(self, args_10style, kwargs_10style, execution_options)
  File "C:\Users\ustad\Desktop\arsaanalizvesunum\venv\lib\site-packages\sqlalchemy\sql\elements.py", line 334, in _execute_on_connection
    return connection._execute_clauseelement(
  File "C:\Users\ustad\Desktop\arsaanalizvesunum\venv\lib\site-packages\sqlalchemy\engine\base.py", line 1577, in _execute_clauseelement
    ret = self._execute_context(
  File "C:\Users\ustad\Desktop\arsaanalizvesunum\venv\lib\site-packages\sqlalchemy\engine\base.py", line 1953, in _execute_context
    self._handle_dbapi_exception(
  File "C:\Users\ustad\Desktop\arsaanalizvesunum\venv\lib\site-packages\sqlalchemy\engine\base.py", line 2134, in _handle_dbapi_exception
    util.raise_(
  File "C:\Users\ustad\Desktop\arsaanalizvesunum\venv\lib\site-packages\sqlalchemy\util\compat.py", line 211, in raise_
    raise exception
  File "C:\Users\ustad\Desktop\arsaanalizvesunum\venv\lib\site-packages\sqlalchemy\engine\base.py", line 1910, in _execute_context
    self.dialect.do_execute(
  File "C:\Users\ustad\Desktop\arsaanalizvesunum\venv\lib\site-packages\sqlalchemy\engine\default.py", line 736, in do_execute
    cursor.execute(statement, parameters)
sqlalchemy.exc.OperationalError: (pyodbc.OperationalError) ('08S01', '[08S01] [Microsoft][ODBC Driver 18 for SQL Server]TCP Sağlayıcısı: Bağlanılan uygun olarak belli bir süre içinde yanıt vermediğinden veya kurulan\r\nbağlantı bağlanılan ana bilgisayar yanıt vermediğinden bir bağlantı kurulamadı.\r\n (10060) (SQLExecDirectW); [08S01] [Microsoft][ODBC Driver 18 for SQL Server]İletişim bağlantısı hatası (10060)')
[SQL: SELECT users.id AS users_id, users.email AS users_email, users.password_hash AS users_password_hash, users.registered_on AS users_registered_on, users.ad AS users_ad, users.soyad AS users_soyad, users.telefon AS users_telefon, users.firma AS users_firma, users.unvan AS users_unvan, users.adres AS users_adres, users.profil_foto AS users_profil_foto, users.is_active AS users_is_active, users.son_giris AS users_son_giris, users.failed_attempts AS users_failed_attempts, users.reset_token AS users_reset_token, users.reset_token_expires AS users_reset_token_expires, users.timezone AS users_timezone, users.role AS users_role, users.office_id AS users_office_id, users.reports_to_user_id AS users_reports_to_user_id 
FROM users 
WHERE users.id = ?]
[parameters: (4,)]
(Background on this error at: https://sqlalche.me/e/14/e3q8)

2025-05-15 02:09:47,908 - ERROR - app - Sunucu hatası oluştu: (pyodbc.OperationalError) ('08001', '[08001] [Microsoft][ODBC Driver 18 for SQL Server]Adlandırılmış Kanal Sağlayıcısı: SQL Server için bağlantı açılamadı [53].  (53) (SQLDriverConnect); [08001] [Microsoft][ODBC Driver 18 for SQL Server]Oturum açma zaman aşımı doldu (0); [08001] [Microsoft][ODBC Driver 18 for SQL Server]46.221.49.106 bağlantısı kurulurken ağla ilgili veya örneğe özgü bir hata oluştu. Sunucu bulunamadı veya sunucuya erişilemiyor. Örnek adının doğru olup olmadığını ve SQL Server’ın uzak bağlantılara izin verecek şekilde yapılandırılıp yapılandırılmadığını kontrol edin. Daha fazla bilgi için Microsoft SQL Server Çevrimiçi Kitapları’na bakın. (53)')
(Background on this error at: https://sqlalche.me/e/14/e3q8)
Traceback:
Traceback (most recent call last):
  File "C:\Users\ustad\Desktop\arsaanalizvesunum\venv\lib\site-packages\sqlalchemy\engine\base.py", line 3371, in _wrap_pool_connect
    return fn()
  File "C:\Users\ustad\Desktop\arsaanalizvesunum\venv\lib\site-packages\sqlalchemy\pool\base.py", line 327, in connect
    return _ConnectionFairy._checkout(self)
  File "C:\Users\ustad\Desktop\arsaanalizvesunum\venv\lib\site-packages\sqlalchemy\pool\base.py", line 894, in _checkout
    fairy = _ConnectionRecord.checkout(pool)
  File "C:\Users\ustad\Desktop\arsaanalizvesunum\venv\lib\site-packages\sqlalchemy\pool\base.py", line 498, in checkout
    rec._checkin_failed(err, _fairy_was_created=False)
  File "C:\Users\ustad\Desktop\arsaanalizvesunum\venv\lib\site-packages\sqlalchemy\util\langhelpers.py", line 70, in __exit__
    compat.raise_(
  File "C:\Users\ustad\Desktop\arsaanalizvesunum\venv\lib\site-packages\sqlalchemy\util\compat.py", line 211, in raise_
    raise exception
  File "C:\Users\ustad\Desktop\arsaanalizvesunum\venv\lib\site-packages\sqlalchemy\pool\base.py", line 495, in checkout
    dbapi_connection = rec.get_connection()
  File "C:\Users\ustad\Desktop\arsaanalizvesunum\venv\lib\site-packages\sqlalchemy\pool\base.py", line 630, in get_connection
    self.__connect()
  File "C:\Users\ustad\Desktop\arsaanalizvesunum\venv\lib\site-packages\sqlalchemy\pool\base.py", line 691, in __connect
    pool.logger.debug("Error on connect(): %s", e)
  File "C:\Users\ustad\Desktop\arsaanalizvesunum\venv\lib\site-packages\sqlalchemy\util\langhelpers.py", line 70, in __exit__
    compat.raise_(
  File "C:\Users\ustad\Desktop\arsaanalizvesunum\venv\lib\site-packages\sqlalchemy\util\compat.py", line 211, in raise_
    raise exception
  File "C:\Users\ustad\Desktop\arsaanalizvesunum\venv\lib\site-packages\sqlalchemy\pool\base.py", line 686, in __connect
    self.dbapi_connection = connection = pool._invoke_creator(self)
  File "C:\Users\ustad\Desktop\arsaanalizvesunum\venv\lib\site-packages\sqlalchemy\engine\create.py", line 574, in connect
    return dialect.connect(*cargs, **cparams)
  File "C:\Users\ustad\Desktop\arsaanalizvesunum\venv\lib\site-packages\sqlalchemy\engine\default.py", line 598, in connect
    return self.dbapi.connect(*cargs, **cparams)
pyodbc.OperationalError: ('08001', '[08001] [Microsoft][ODBC Driver 18 for SQL Server]Adlandırılmış Kanal Sağlayıcısı: SQL Server için bağlantı açılamadı [53].  (53) (SQLDriverConnect); [08001] [Microsoft][ODBC Driver 18 for SQL Server]Oturum açma zaman aşımı doldu (0); [08001] [Microsoft][ODBC Driver 18 for SQL Server]46.221.49.106 bağlantısı kurulurken ağla ilgili veya örneğe özgü bir hata oluştu. Sunucu bulunamadı veya sunucuya erişilemiyor. Örnek adının doğru olup olmadığını ve SQL Server’ın uzak bağlantılara izin verecek şekilde yapılandırılıp yapılandırılmadığını kontrol edin. Daha fazla bilgi için Microsoft SQL Server Çevrimiçi Kitapları’na bakın. (53)')

The above exception was the direct cause of the following exception:

Traceback (most recent call last):
  File "C:\Users\ustad\Desktop\arsaanalizvesunum\venv\lib\site-packages\flask\app.py", line 1513, in full_dispatch_request
    rv = self.dispatch_request()
  File "C:\Users\ustad\Desktop\arsaanalizvesunum\venv\lib\site-packages\flask\app.py", line 1499, in dispatch_request
    return self.ensure_sync(self.view_functions[rule.endpoint])(**req.view_args)
  File "C:\Users\ustad\Desktop\arsaanalizvesunum\venv\lib\site-packages\flask_login\utils.py", line 284, in decorated_view
    elif not current_user.is_authenticated:
  File "C:\Users\ustad\Desktop\arsaanalizvesunum\venv\lib\site-packages\werkzeug\local.py", line 422, in __get__
    obj = instance._get_current_object()
  File "C:\Users\ustad\Desktop\arsaanalizvesunum\venv\lib\site-packages\werkzeug\local.py", line 544, in _get_current_object
    return self.__local()  # type: ignore
  File "C:\Users\ustad\Desktop\arsaanalizvesunum\venv\lib\site-packages\flask_login\utils.py", line 25, in <lambda>
    current_user = LocalProxy(lambda: _get_user())
  File "C:\Users\ustad\Desktop\arsaanalizvesunum\venv\lib\site-packages\flask_login\utils.py", line 370, in _get_user
    current_app.login_manager._load_user()
  File "C:\Users\ustad\Desktop\arsaanalizvesunum\venv\lib\site-packages\flask_login\login_manager.py", line 364, in _load_user
    user = self._user_callback(user_id)
  File "c:\Users\ustad\Desktop\arsaanalizvesunum\app.py", line 79, in load_user
    return User.query.get(int(user_id))
  File "<string>", line 2, in get
  File "C:\Users\ustad\Desktop\arsaanalizvesunum\venv\lib\site-packages\sqlalchemy\util\deprecations.py", line 468, in warned
    return fn(*args, **kwargs)
  File "C:\Users\ustad\Desktop\arsaanalizvesunum\venv\lib\site-packages\sqlalchemy\orm\query.py", line 947, in get
    return self._get_impl(ident, loading.load_on_pk_identity)
  File "C:\Users\ustad\Desktop\arsaanalizvesunum\venv\lib\site-packages\sqlalchemy\orm\query.py", line 951, in _get_impl
    return self.session._get_impl(
  File "C:\Users\ustad\Desktop\arsaanalizvesunum\venv\lib\site-packages\sqlalchemy\orm\session.py", line 2975, in _get_impl
    return db_load_fn(
  File "C:\Users\ustad\Desktop\arsaanalizvesunum\venv\lib\site-packages\sqlalchemy\orm\loading.py", line 530, in load_on_pk_identity
    session.execute(
  File "C:\Users\ustad\Desktop\arsaanalizvesunum\venv\lib\site-packages\sqlalchemy\orm\session.py", line 1716, in execute
    conn = self._connection_for_bind(bind)
  File "C:\Users\ustad\Desktop\arsaanalizvesunum\venv\lib\site-packages\sqlalchemy\orm\session.py", line 1555, in _connection_for_bind
    return self._transaction._connection_for_bind(
  File "C:\Users\ustad\Desktop\arsaanalizvesunum\venv\lib\site-packages\sqlalchemy\orm\session.py", line 750, in _connection_for_bind
    conn = bind.connect()
  File "C:\Users\ustad\Desktop\arsaanalizvesunum\venv\lib\site-packages\sqlalchemy\engine\base.py", line 3325, in connect
    return self._connection_cls(self, close_with_result=close_with_result)
  File "C:\Users\ustad\Desktop\arsaanalizvesunum\venv\lib\site-packages\sqlalchemy\engine\base.py", line 96, in __init__
    else engine.raw_connection()
  File "C:\Users\ustad\Desktop\arsaanalizvesunum\venv\lib\site-packages\sqlalchemy\engine\base.py", line 3404, in raw_connection
    return self._wrap_pool_connect(self.pool.connect, _connection)
  File "C:\Users\ustad\Desktop\arsaanalizvesunum\venv\lib\site-packages\sqlalchemy\engine\base.py", line 3374, in _wrap_pool_connect
    Connection._handle_dbapi_exception_noconnection(
  File "C:\Users\ustad\Desktop\arsaanalizvesunum\venv\lib\site-packages\sqlalchemy\engine\base.py", line 2208, in _handle_dbapi_exception_noconnection
    util.raise_(
  File "C:\Users\ustad\Desktop\arsaanalizvesunum\venv\lib\site-packages\sqlalchemy\util\compat.py", line 211, in raise_
    raise exception
  File "C:\Users\ustad\Desktop\arsaanalizvesunum\venv\lib\site-packages\sqlalchemy\engine\base.py", line 3371, in _wrap_pool_connect
    return fn()
  File "C:\Users\ustad\Desktop\arsaanalizvesunum\venv\lib\site-packages\sqlalchemy\pool\base.py", line 327, in connect
    return _ConnectionFairy._checkout(self)
  File "C:\Users\ustad\Desktop\arsaanalizvesunum\venv\lib\site-packages\sqlalchemy\pool\base.py", line 894, in _checkout
    fairy = _ConnectionRecord.checkout(pool)
  File "C:\Users\ustad\Desktop\arsaanalizvesunum\venv\lib\site-packages\sqlalchemy\pool\base.py", line 498, in checkout
    rec._checkin_failed(err, _fairy_was_created=False)
  File "C:\Users\ustad\Desktop\arsaanalizvesunum\venv\lib\site-packages\sqlalchemy\util\langhelpers.py", line 70, in __exit__
    compat.raise_(
  File "C:\Users\ustad\Desktop\arsaanalizvesunum\venv\lib\site-packages\sqlalchemy\util\compat.py", line 211, in raise_
    raise exception
  File "C:\Users\ustad\Desktop\arsaanalizvesunum\venv\lib\site-packages\sqlalchemy\pool\base.py", line 495, in checkout
    dbapi_connection = rec.get_connection()
  File "C:\Users\ustad\Desktop\arsaanalizvesunum\venv\lib\site-packages\sqlalchemy\pool\base.py", line 630, in get_connection
    self.__connect()
  File "C:\Users\ustad\Desktop\arsaanalizvesunum\venv\lib\site-packages\sqlalchemy\pool\base.py", line 691, in __connect
    pool.logger.debug("Error on connect(): %s", e)
  File "C:\Users\ustad\Desktop\arsaanalizvesunum\venv\lib\site-packages\sqlalchemy\util\langhelpers.py", line 70, in __exit__
    compat.raise_(
  File "C:\Users\ustad\Desktop\arsaanalizvesunum\venv\lib\site-packages\sqlalchemy\util\compat.py", line 211, in raise_
    raise exception
  File "C:\Users\ustad\Desktop\arsaanalizvesunum\venv\lib\site-packages\sqlalchemy\pool\base.py", line 686, in __connect
    self.dbapi_connection = connection = pool._invoke_creator(self)
  File "C:\Users\ustad\Desktop\arsaanalizvesunum\venv\lib\site-packages\sqlalchemy\engine\create.py", line 574, in connect
    return dialect.connect(*cargs, **cparams)
  File "C:\Users\ustad\Desktop\arsaanalizvesunum\venv\lib\site-packages\sqlalchemy\engine\default.py", line 598, in connect
    return self.dbapi.connect(*cargs, **cparams)
sqlalchemy.exc.OperationalError: (pyodbc.OperationalError) ('08001', '[08001] [Microsoft][ODBC Driver 18 for SQL Server]Adlandırılmış Kanal Sağlayıcısı: SQL Server için bağlantı açılamadı [53].  (53) (SQLDriverConnect); [08001] [Microsoft][ODBC Driver 18 for SQL Server]Oturum açma zaman aşımı doldu (0); [08001] [Microsoft][ODBC Driver 18 for SQL Server]46.221.49.106 bağlantısı kurulurken ağla ilgili veya örneğe özgü bir hata oluştu. Sunucu bulunamadı veya sunucuya erişilemiyor. Örnek adının doğru olup olmadığını ve SQL Server’ın uzak bağlantılara izin verecek şekilde yapılandırılıp yapılandırılmadığını kontrol edin. Daha fazla bilgi için Microsoft SQL Server Çevrimiçi Kitapları’na bakın. (53)')
(Background on this error at: https://sqlalche.me/e/14/e3q8)

2025-05-15 02:09:47,909 - ERROR - app - Sunucu hatası oluştu: (pyodbc.OperationalError) ('08001', '[08001] [Microsoft][ODBC Driver 18 for SQL Server]Adlandırılmış Kanal Sağlayıcısı: SQL Server için bağlantı açılamadı [53].  (53) (SQLDriverConnect); [08001] [Microsoft][ODBC Driver 18 for SQL Server]Oturum açma zaman aşımı doldu (0); [08001] [Microsoft][ODBC Driver 18 for SQL Server]46.221.49.106 bağlantısı kurulurken ağla ilgili veya örneğe özgü bir hata oluştu. Sunucu bulunamadı veya sunucuya erişilemiyor. Örnek adının doğru olup olmadığını ve SQL Server’ın uzak bağlantılara izin verecek şekilde yapılandırılıp yapılandırılmadığını kontrol edin. Daha fazla bilgi için Microsoft SQL Server Çevrimiçi Kitapları’na bakın. (53)')
(Background on this error at: https://sqlalche.me/e/14/e3q8)
Traceback:
Traceback (most recent call last):
  File "C:\Users\ustad\Desktop\arsaanalizvesunum\venv\lib\site-packages\sqlalchemy\engine\base.py", line 3371, in _wrap_pool_connect
    return fn()
  File "C:\Users\ustad\Desktop\arsaanalizvesunum\venv\lib\site-packages\sqlalchemy\pool\base.py", line 327, in connect
    return _ConnectionFairy._checkout(self)
  File "C:\Users\ustad\Desktop\arsaanalizvesunum\venv\lib\site-packages\sqlalchemy\pool\base.py", line 894, in _checkout
    fairy = _ConnectionRecord.checkout(pool)
  File "C:\Users\ustad\Desktop\arsaanalizvesunum\venv\lib\site-packages\sqlalchemy\pool\base.py", line 493, in checkout
    rec = pool._do_get()
  File "C:\Users\ustad\Desktop\arsaanalizvesunum\venv\lib\site-packages\sqlalchemy\pool\impl.py", line 146, in _do_get
    self._dec_overflow()
  File "C:\Users\ustad\Desktop\arsaanalizvesunum\venv\lib\site-packages\sqlalchemy\util\langhelpers.py", line 70, in __exit__
    compat.raise_(
  File "C:\Users\ustad\Desktop\arsaanalizvesunum\venv\lib\site-packages\sqlalchemy\util\compat.py", line 211, in raise_
    raise exception
  File "C:\Users\ustad\Desktop\arsaanalizvesunum\venv\lib\site-packages\sqlalchemy\pool\impl.py", line 143, in _do_get
    return self._create_connection()
  File "C:\Users\ustad\Desktop\arsaanalizvesunum\venv\lib\site-packages\sqlalchemy\pool\base.py", line 273, in _create_connection
    return _ConnectionRecord(self)
  File "C:\Users\ustad\Desktop\arsaanalizvesunum\venv\lib\site-packages\sqlalchemy\pool\base.py", line 388, in __init__
    self.__connect()
  File "C:\Users\ustad\Desktop\arsaanalizvesunum\venv\lib\site-packages\sqlalchemy\pool\base.py", line 691, in __connect
    pool.logger.debug("Error on connect(): %s", e)
  File "C:\Users\ustad\Desktop\arsaanalizvesunum\venv\lib\site-packages\sqlalchemy\util\langhelpers.py", line 70, in __exit__
    compat.raise_(
  File "C:\Users\ustad\Desktop\arsaanalizvesunum\venv\lib\site-packages\sqlalchemy\util\compat.py", line 211, in raise_
    raise exception
  File "C:\Users\ustad\Desktop\arsaanalizvesunum\venv\lib\site-packages\sqlalchemy\pool\base.py", line 686, in __connect
    self.dbapi_connection = connection = pool._invoke_creator(self)
  File "C:\Users\ustad\Desktop\arsaanalizvesunum\venv\lib\site-packages\sqlalchemy\engine\create.py", line 574, in connect
    return dialect.connect(*cargs, **cparams)
  File "C:\Users\ustad\Desktop\arsaanalizvesunum\venv\lib\site-packages\sqlalchemy\engine\default.py", line 598, in connect
    return self.dbapi.connect(*cargs, **cparams)
pyodbc.OperationalError: ('08001', '[08001] [Microsoft][ODBC Driver 18 for SQL Server]Adlandırılmış Kanal Sağlayıcısı: SQL Server için bağlantı açılamadı [53].  (53) (SQLDriverConnect); [08001] [Microsoft][ODBC Driver 18 for SQL Server]Oturum açma zaman aşımı doldu (0); [08001] [Microsoft][ODBC Driver 18 for SQL Server]46.221.49.106 bağlantısı kurulurken ağla ilgili veya örneğe özgü bir hata oluştu. Sunucu bulunamadı veya sunucuya erişilemiyor. Örnek adının doğru olup olmadığını ve SQL Server’ın uzak bağlantılara izin verecek şekilde yapılandırılıp yapılandırılmadığını kontrol edin. Daha fazla bilgi için Microsoft SQL Server Çevrimiçi Kitapları’na bakın. (53)')

The above exception was the direct cause of the following exception:

Traceback (most recent call last):
  File "C:\Users\ustad\Desktop\arsaanalizvesunum\venv\lib\site-packages\flask\app.py", line 1513, in full_dispatch_request
    rv = self.dispatch_request()
  File "C:\Users\ustad\Desktop\arsaanalizvesunum\venv\lib\site-packages\flask\app.py", line 1499, in dispatch_request
    return self.ensure_sync(self.view_functions[rule.endpoint])(**req.view_args)
  File "C:\Users\ustad\Desktop\arsaanalizvesunum\venv\lib\site-packages\flask_login\utils.py", line 284, in decorated_view
    elif not current_user.is_authenticated:
  File "C:\Users\ustad\Desktop\arsaanalizvesunum\venv\lib\site-packages\werkzeug\local.py", line 422, in __get__
    obj = instance._get_current_object()
  File "C:\Users\ustad\Desktop\arsaanalizvesunum\venv\lib\site-packages\werkzeug\local.py", line 544, in _get_current_object
    return self.__local()  # type: ignore
  File "C:\Users\ustad\Desktop\arsaanalizvesunum\venv\lib\site-packages\flask_login\utils.py", line 25, in <lambda>
    current_user = LocalProxy(lambda: _get_user())
  File "C:\Users\ustad\Desktop\arsaanalizvesunum\venv\lib\site-packages\flask_login\utils.py", line 370, in _get_user
    current_app.login_manager._load_user()
  File "C:\Users\ustad\Desktop\arsaanalizvesunum\venv\lib\site-packages\flask_login\login_manager.py", line 364, in _load_user
    user = self._user_callback(user_id)
  File "c:\Users\ustad\Desktop\arsaanalizvesunum\app.py", line 79, in load_user
    return User.query.get(int(user_id))
  File "<string>", line 2, in get
  File "C:\Users\ustad\Desktop\arsaanalizvesunum\venv\lib\site-packages\sqlalchemy\util\deprecations.py", line 468, in warned
    return fn(*args, **kwargs)
  File "C:\Users\ustad\Desktop\arsaanalizvesunum\venv\lib\site-packages\sqlalchemy\orm\query.py", line 947, in get
    return self._get_impl(ident, loading.load_on_pk_identity)
  File "C:\Users\ustad\Desktop\arsaanalizvesunum\venv\lib\site-packages\sqlalchemy\orm\query.py", line 951, in _get_impl
    return self.session._get_impl(
  File "C:\Users\ustad\Desktop\arsaanalizvesunum\venv\lib\site-packages\sqlalchemy\orm\session.py", line 2975, in _get_impl
    return db_load_fn(
  File "C:\Users\ustad\Desktop\arsaanalizvesunum\venv\lib\site-packages\sqlalchemy\orm\loading.py", line 530, in load_on_pk_identity
    session.execute(
  File "C:\Users\ustad\Desktop\arsaanalizvesunum\venv\lib\site-packages\sqlalchemy\orm\session.py", line 1716, in execute
    conn = self._connection_for_bind(bind)
  File "C:\Users\ustad\Desktop\arsaanalizvesunum\venv\lib\site-packages\sqlalchemy\orm\session.py", line 1555, in _connection_for_bind
    return self._transaction._connection_for_bind(
  File "C:\Users\ustad\Desktop\arsaanalizvesunum\venv\lib\site-packages\sqlalchemy\orm\session.py", line 750, in _connection_for_bind
    conn = bind.connect()
  File "C:\Users\ustad\Desktop\arsaanalizvesunum\venv\lib\site-packages\sqlalchemy\engine\base.py", line 3325, in connect
    return self._connection_cls(self, close_with_result=close_with_result)
  File "C:\Users\ustad\Desktop\arsaanalizvesunum\venv\lib\site-packages\sqlalchemy\engine\base.py", line 96, in __init__
    else engine.raw_connection()
  File "C:\Users\ustad\Desktop\arsaanalizvesunum\venv\lib\site-packages\sqlalchemy\engine\base.py", line 3404, in raw_connection
    return self._wrap_pool_connect(self.pool.connect, _connection)
  File "C:\Users\ustad\Desktop\arsaanalizvesunum\venv\lib\site-packages\sqlalchemy\engine\base.py", line 3374, in _wrap_pool_connect
    Connection._handle_dbapi_exception_noconnection(
  File "C:\Users\ustad\Desktop\arsaanalizvesunum\venv\lib\site-packages\sqlalchemy\engine\base.py", line 2208, in _handle_dbapi_exception_noconnection
    util.raise_(
  File "C:\Users\ustad\Desktop\arsaanalizvesunum\venv\lib\site-packages\sqlalchemy\util\compat.py", line 211, in raise_
    raise exception
  File "C:\Users\ustad\Desktop\arsaanalizvesunum\venv\lib\site-packages\sqlalchemy\engine\base.py", line 3371, in _wrap_pool_connect
    return fn()
  File "C:\Users\ustad\Desktop\arsaanalizvesunum\venv\lib\site-packages\sqlalchemy\pool\base.py", line 327, in connect
    return _ConnectionFairy._checkout(self)
  File "C:\Users\ustad\Desktop\arsaanalizvesunum\venv\lib\site-packages\sqlalchemy\pool\base.py", line 894, in _checkout
    fairy = _ConnectionRecord.checkout(pool)
  File "C:\Users\ustad\Desktop\arsaanalizvesunum\venv\lib\site-packages\sqlalchemy\pool\base.py", line 493, in checkout
    rec = pool._do_get()
  File "C:\Users\ustad\Desktop\arsaanalizvesunum\venv\lib\site-packages\sqlalchemy\pool\impl.py", line 146, in _do_get
    self._dec_overflow()
  File "C:\Users\ustad\Desktop\arsaanalizvesunum\venv\lib\site-packages\sqlalchemy\util\langhelpers.py", line 70, in __exit__
    compat.raise_(
  File "C:\Users\ustad\Desktop\arsaanalizvesunum\venv\lib\site-packages\sqlalchemy\util\compat.py", line 211, in raise_
    raise exception
  File "C:\Users\ustad\Desktop\arsaanalizvesunum\venv\lib\site-packages\sqlalchemy\pool\impl.py", line 143, in _do_get
    return self._create_connection()
  File "C:\Users\ustad\Desktop\arsaanalizvesunum\venv\lib\site-packages\sqlalchemy\pool\base.py", line 273, in _create_connection
    return _ConnectionRecord(self)
  File "C:\Users\ustad\Desktop\arsaanalizvesunum\venv\lib\site-packages\sqlalchemy\pool\base.py", line 388, in __init__
    self.__connect()
  File "C:\Users\ustad\Desktop\arsaanalizvesunum\venv\lib\site-packages\sqlalchemy\pool\base.py", line 691, in __connect
    pool.logger.debug("Error on connect(): %s", e)
  File "C:\Users\ustad\Desktop\arsaanalizvesunum\venv\lib\site-packages\sqlalchemy\util\langhelpers.py", line 70, in __exit__
    compat.raise_(
  File "C:\Users\ustad\Desktop\arsaanalizvesunum\venv\lib\site-packages\sqlalchemy\util\compat.py", line 211, in raise_
    raise exception
  File "C:\Users\ustad\Desktop\arsaanalizvesunum\venv\lib\site-packages\sqlalchemy\pool\base.py", line 686, in __connect
    self.dbapi_connection = connection = pool._invoke_creator(self)
  File "C:\Users\ustad\Desktop\arsaanalizvesunum\venv\lib\site-packages\sqlalchemy\engine\create.py", line 574, in connect
    return dialect.connect(*cargs, **cparams)
  File "C:\Users\ustad\Desktop\arsaanalizvesunum\venv\lib\site-packages\sqlalchemy\engine\default.py", line 598, in connect
    return self.dbapi.connect(*cargs, **cparams)
sqlalchemy.exc.OperationalError: (pyodbc.OperationalError) ('08001', '[08001] [Microsoft][ODBC Driver 18 for SQL Server]Adlandırılmış Kanal Sağlayıcısı: SQL Server için bağlantı açılamadı [53].  (53) (SQLDriverConnect); [08001] [Microsoft][ODBC Driver 18 for SQL Server]Oturum açma zaman aşımı doldu (0); [08001] [Microsoft][ODBC Driver 18 for SQL Server]46.221.49.106 bağlantısı kurulurken ağla ilgili veya örneğe özgü bir hata oluştu. Sunucu bulunamadı veya sunucuya erişilemiyor. Örnek adının doğru olup olmadığını ve SQL Server’ın uzak bağlantılara izin verecek şekilde yapılandırılıp yapılandırılmadığını kontrol edin. Daha fazla bilgi için Microsoft SQL Server Çevrimiçi Kitapları’na bakın. (53)')
(Background on this error at: https://sqlalche.me/e/14/e3q8)

2025-05-15 02:10:08,754 - ERROR - app - Sunucu hatası oluştu: _messages.html
Traceback:
Traceback (most recent call last):
  File "C:\Users\ustad\Desktop\arsaanalizvesunum\venv\lib\site-packages\flask\app.py", line 1513, in full_dispatch_request
    rv = self.dispatch_request()
  File "C:\Users\ustad\Desktop\arsaanalizvesunum\venv\lib\site-packages\flask\app.py", line 1499, in dispatch_request
    return self.ensure_sync(self.view_functions[rule.endpoint])(**req.view_args)
  File "C:\Users\ustad\Desktop\arsaanalizvesunum\venv\lib\site-packages\flask_login\utils.py", line 290, in decorated_view
    return current_app.ensure_sync(func)(*args, **kwargs)
  File "c:\Users\ustad\Desktop\arsaanalizvesunum\blueprints\auth_decorators.py", line 15, in decorated_function
    return f(*args, **kwargs)
  File "c:\Users\ustad\Desktop\arsaanalizvesunum\blueprints\admin_bp.py", line 90, in create_office
    return render_template('create_office.html')
  File "C:\Users\ustad\Desktop\arsaanalizvesunum\venv\lib\site-packages\flask\templating.py", line 147, in render_template
    return _render(
  File "C:\Users\ustad\Desktop\arsaanalizvesunum\venv\lib\site-packages\flask\templating.py", line 128, in _render
    rv = template.render(context)
  File "C:\Users\ustad\Desktop\arsaanalizvesunum\venv\lib\site-packages\jinja2\environment.py", line 1295, in render
    self.environment.handle_exception()
  File "C:\Users\ustad\Desktop\arsaanalizvesunum\venv\lib\site-packages\jinja2\environment.py", line 942, in handle_exception
    raise rewrite_traceback_stack(source=source)
  File "c:\Users\ustad\Desktop\arsaanalizvesunum\templates\admin\create_office.html", line 1, in top-level template code
    {% extends "base_admin.html" %}
  File "c:\Users\ustad\Desktop\arsaanalizvesunum\templates\admin\base_admin.html", line 33, in top-level template code
    {% block content %}{% endblock %}
  File "c:\Users\ustad\Desktop\arsaanalizvesunum\templates\admin\create_office.html", line 14, in block 'content'
    {% include "_messages.html" %}
  File "C:\Users\ustad\Desktop\arsaanalizvesunum\venv\lib\site-packages\flask\templating.py", line 59, in get_source
    return self._get_source_fast(environment, template)
  File "C:\Users\ustad\Desktop\arsaanalizvesunum\venv\lib\site-packages\flask\templating.py", line 95, in _get_source_fast
    raise TemplateNotFound(template)
jinja2.exceptions.TemplateNotFound: _messages.html

2025-05-15 02:12:29,705 - ERROR - app - Sunucu hatası oluştu: 404 Not Found: The requested URL was not found on the server. If you entered the URL manually please check your spelling and try again.
Traceback:
Traceback (most recent call last):
  File "C:\Users\ustad\Desktop\arsaanalizvesunum\venv\lib\site-packages\flask\app.py", line 1513, in full_dispatch_request
    rv = self.dispatch_request()
  File "C:\Users\ustad\Desktop\arsaanalizvesunum\venv\lib\site-packages\flask\app.py", line 1499, in dispatch_request
    return self.ensure_sync(self.view_functions[rule.endpoint])(**req.view_args)
  File "C:\Users\ustad\Desktop\arsaanalizvesunum\venv\lib\site-packages\flask\app.py", line 518, in <lambda>
    view_func=lambda **kw: self_ref().send_static_file(**kw),  # type: ignore # noqa: B950
  File "C:\Users\ustad\Desktop\arsaanalizvesunum\venv\lib\site-packages\flask\scaffold.py", line 328, in send_static_file
    return send_from_directory(
  File "C:\Users\ustad\Desktop\arsaanalizvesunum\venv\lib\site-packages\flask\helpers.py", line 700, in send_from_directory
    return werkzeug.utils.send_from_directory(  # type: ignore
  File "C:\Users\ustad\Desktop\arsaanalizvesunum\venv\lib\site-packages\werkzeug\utils.py", line 841, in send_from_directory
    raise NotFound()
werkzeug.exceptions.NotFound: 404 Not Found: The requested URL was not found on the server. If you entered the URL manually please check your spelling and try again.

2025-05-15 02:12:35,910 - ERROR - app - Sunucu hatası oluştu: 404 Not Found: The requested URL was not found on the server. If you entered the URL manually please check your spelling and try again.
Traceback:
Traceback (most recent call last):
  File "C:\Users\ustad\Desktop\arsaanalizvesunum\venv\lib\site-packages\flask\app.py", line 1513, in full_dispatch_request
    rv = self.dispatch_request()
  File "C:\Users\ustad\Desktop\arsaanalizvesunum\venv\lib\site-packages\flask\app.py", line 1499, in dispatch_request
    return self.ensure_sync(self.view_functions[rule.endpoint])(**req.view_args)
  File "C:\Users\ustad\Desktop\arsaanalizvesunum\venv\lib\site-packages\flask\app.py", line 518, in <lambda>
    view_func=lambda **kw: self_ref().send_static_file(**kw),  # type: ignore # noqa: B950
  File "C:\Users\ustad\Desktop\arsaanalizvesunum\venv\lib\site-packages\flask\scaffold.py", line 328, in send_static_file
    return send_from_directory(
  File "C:\Users\ustad\Desktop\arsaanalizvesunum\venv\lib\site-packages\flask\helpers.py", line 700, in send_from_directory
    return werkzeug.utils.send_from_directory(  # type: ignore
  File "C:\Users\ustad\Desktop\arsaanalizvesunum\venv\lib\site-packages\werkzeug\utils.py", line 841, in send_from_directory
    raise NotFound()
werkzeug.exceptions.NotFound: 404 Not Found: The requested URL was not found on the server. If you entered the URL manually please check your spelling and try again.

