2025-05-19 01:17:53,442 - ERROR - app - Sunucu hatası oluştu: (pyodbc.ProgrammingError) ('42S22', "[42S22] [Microsoft][ODBC Driver 18 for SQL Server][SQL Server]Invalid column name 'office_id'. (207) (SQLExecDirectW); [42S22] [Microsoft][ODBC Driver 18 for SQL Server][SQL Server]Statement(s) could not be prepared. (8180)")
[SQL: SELECT TOP 5 crm_tasks.id AS crm_tasks_id, crm_tasks.user_id AS crm_tasks_user_id, crm_tasks.contact_id AS crm_tasks_contact_id, crm_tasks.deal_id AS crm_tasks_deal_id, crm_tasks.assigned_to_user_id AS crm_tasks_assigned_to_user_id, crm_tasks.office_id AS crm_tasks_office_id, crm_tasks.title AS crm_tasks_title, crm_tasks.description AS crm_tasks_description, crm_tasks.due_date AS crm_tasks_due_date, crm_tasks.status AS crm_tasks_status, crm_tasks.priority AS crm_tasks_priority, crm_tasks.reminder_enabled AS crm_tasks_reminder_enabled, crm_tasks.reminder_time AS crm_tasks_reminder_time, crm_tasks.is_recurring AS crm_tasks_is_recurring, crm_tasks.recurrence_type AS crm_tasks_recurrence_type, crm_tasks.recurrence_interval AS crm_tasks_recurrence_interval, crm_tasks.recurrence_end_date AS crm_tasks_recurrence_end_date, crm_tasks.completed_at AS crm_tasks_completed_at, crm_tasks.team_id AS crm_tasks_team_id, crm_tasks.assigned_by_user_id AS crm_tasks_assigned_by_user_id, crm_tasks.previous_assignee_id AS crm_tasks_previous_assignee_id, crm_tasks.reassigned_at AS crm_tasks_reassigned_at, crm_tasks.reassigned_by_id AS crm_tasks_reassigned_by_id, crm_tasks.reassignment_reason AS crm_tasks_reassignment_reason, crm_tasks.task_type AS crm_tasks_task_type, crm_tasks.created_at AS crm_tasks_created_at, crm_tasks.updated_at AS crm_tasks_updated_at 
FROM crm_tasks 
WHERE crm_tasks.assigned_to_user_id = ? AND (crm_tasks.status NOT IN (?, ?)) AND crm_tasks.due_date IS NOT NULL AND CAST(crm_tasks.due_date AS DATE) >= ? AND CAST(crm_tasks.due_date AS DATE) <= ? ORDER BY crm_tasks.due_date ASC]
[parameters: (2, 'Tamamlandı', 'İptal Edildi', datetime.datetime(2025, 5, 18, 0, 0), datetime.datetime(2025, 5, 25, 0, 0))]
(Background on this error at: https://sqlalche.me/e/14/f405)
Traceback:
Traceback (most recent call last):
  File "C:\Users\ustad\Desktop\arsaanalizvesunum\venv\lib\site-packages\sqlalchemy\engine\base.py", line 1910, in _execute_context
    self.dialect.do_execute(
  File "C:\Users\ustad\Desktop\arsaanalizvesunum\venv\lib\site-packages\sqlalchemy\engine\default.py", line 736, in do_execute
    cursor.execute(statement, parameters)
pyodbc.ProgrammingError: ('42S22', "[42S22] [Microsoft][ODBC Driver 18 for SQL Server][SQL Server]Invalid column name 'office_id'. (207) (SQLExecDirectW); [42S22] [Microsoft][ODBC Driver 18 for SQL Server][SQL Server]Statement(s) could not be prepared. (8180)")

The above exception was the direct cause of the following exception:

Traceback (most recent call last):
  File "C:\Users\ustad\Desktop\arsaanalizvesunum\venv\lib\site-packages\flask\app.py", line 1513, in full_dispatch_request
    rv = self.dispatch_request()
  File "C:\Users\ustad\Desktop\arsaanalizvesunum\venv\lib\site-packages\flask\app.py", line 1499, in dispatch_request
    return self.ensure_sync(self.view_functions[rule.endpoint])(**req.view_args)
  File "C:\Users\ustad\Desktop\arsaanalizvesunum\venv\lib\site-packages\flask_login\utils.py", line 290, in decorated_view
    return current_app.ensure_sync(func)(*args, **kwargs)
  File "c:\Users\ustad\Desktop\arsaanalizvesunum\blueprints\main_bp.py", line 182, in index
    yaklasan_gorevler = Task.query.filter(
  File "C:\Users\ustad\Desktop\arsaanalizvesunum\venv\lib\site-packages\sqlalchemy\orm\query.py", line 2773, in all
    return self._iter().all()
  File "C:\Users\ustad\Desktop\arsaanalizvesunum\venv\lib\site-packages\sqlalchemy\orm\query.py", line 2916, in _iter
    result = self.session.execute(
  File "C:\Users\ustad\Desktop\arsaanalizvesunum\venv\lib\site-packages\sqlalchemy\orm\session.py", line 1717, in execute
    result = conn._execute_20(statement, params or {}, execution_options)
  File "C:\Users\ustad\Desktop\arsaanalizvesunum\venv\lib\site-packages\sqlalchemy\engine\base.py", line 1710, in _execute_20
    return meth(self, args_10style, kwargs_10style, execution_options)
  File "C:\Users\ustad\Desktop\arsaanalizvesunum\venv\lib\site-packages\sqlalchemy\sql\elements.py", line 334, in _execute_on_connection
    return connection._execute_clauseelement(
  File "C:\Users\ustad\Desktop\arsaanalizvesunum\venv\lib\site-packages\sqlalchemy\engine\base.py", line 1577, in _execute_clauseelement
    ret = self._execute_context(
  File "C:\Users\ustad\Desktop\arsaanalizvesunum\venv\lib\site-packages\sqlalchemy\engine\base.py", line 1953, in _execute_context
    self._handle_dbapi_exception(
  File "C:\Users\ustad\Desktop\arsaanalizvesunum\venv\lib\site-packages\sqlalchemy\engine\base.py", line 2134, in _handle_dbapi_exception
    util.raise_(
  File "C:\Users\ustad\Desktop\arsaanalizvesunum\venv\lib\site-packages\sqlalchemy\util\compat.py", line 211, in raise_
    raise exception
  File "C:\Users\ustad\Desktop\arsaanalizvesunum\venv\lib\site-packages\sqlalchemy\engine\base.py", line 1910, in _execute_context
    self.dialect.do_execute(
  File "C:\Users\ustad\Desktop\arsaanalizvesunum\venv\lib\site-packages\sqlalchemy\engine\default.py", line 736, in do_execute
    cursor.execute(statement, parameters)
sqlalchemy.exc.ProgrammingError: (pyodbc.ProgrammingError) ('42S22', "[42S22] [Microsoft][ODBC Driver 18 for SQL Server][SQL Server]Invalid column name 'office_id'. (207) (SQLExecDirectW); [42S22] [Microsoft][ODBC Driver 18 for SQL Server][SQL Server]Statement(s) could not be prepared. (8180)")
[SQL: SELECT TOP 5 crm_tasks.id AS crm_tasks_id, crm_tasks.user_id AS crm_tasks_user_id, crm_tasks.contact_id AS crm_tasks_contact_id, crm_tasks.deal_id AS crm_tasks_deal_id, crm_tasks.assigned_to_user_id AS crm_tasks_assigned_to_user_id, crm_tasks.office_id AS crm_tasks_office_id, crm_tasks.title AS crm_tasks_title, crm_tasks.description AS crm_tasks_description, crm_tasks.due_date AS crm_tasks_due_date, crm_tasks.status AS crm_tasks_status, crm_tasks.priority AS crm_tasks_priority, crm_tasks.reminder_enabled AS crm_tasks_reminder_enabled, crm_tasks.reminder_time AS crm_tasks_reminder_time, crm_tasks.is_recurring AS crm_tasks_is_recurring, crm_tasks.recurrence_type AS crm_tasks_recurrence_type, crm_tasks.recurrence_interval AS crm_tasks_recurrence_interval, crm_tasks.recurrence_end_date AS crm_tasks_recurrence_end_date, crm_tasks.completed_at AS crm_tasks_completed_at, crm_tasks.team_id AS crm_tasks_team_id, crm_tasks.assigned_by_user_id AS crm_tasks_assigned_by_user_id, crm_tasks.previous_assignee_id AS crm_tasks_previous_assignee_id, crm_tasks.reassigned_at AS crm_tasks_reassigned_at, crm_tasks.reassigned_by_id AS crm_tasks_reassigned_by_id, crm_tasks.reassignment_reason AS crm_tasks_reassignment_reason, crm_tasks.task_type AS crm_tasks_task_type, crm_tasks.created_at AS crm_tasks_created_at, crm_tasks.updated_at AS crm_tasks_updated_at 
FROM crm_tasks 
WHERE crm_tasks.assigned_to_user_id = ? AND (crm_tasks.status NOT IN (?, ?)) AND crm_tasks.due_date IS NOT NULL AND CAST(crm_tasks.due_date AS DATE) >= ? AND CAST(crm_tasks.due_date AS DATE) <= ? ORDER BY crm_tasks.due_date ASC]
[parameters: (2, 'Tamamlandı', 'İptal Edildi', datetime.datetime(2025, 5, 18, 0, 0), datetime.datetime(2025, 5, 25, 0, 0))]
(Background on this error at: https://sqlalche.me/e/14/f405)

2025-05-19 01:18:42,646 - ERROR - app - Sunucu hatası oluştu: (pyodbc.ProgrammingError) ('42S22', "[42S22] [Microsoft][ODBC Driver 18 for SQL Server][SQL Server]Invalid column name 'office_id'. (207) (SQLExecDirectW); [42S22] [Microsoft][ODBC Driver 18 for SQL Server][SQL Server]Statement(s) could not be prepared. (8180)")
[SQL: SELECT TOP 5 crm_contacts.id AS crm_contacts_id, crm_contacts.user_id AS crm_contacts_user_id, crm_contacts.company_id AS crm_contacts_company_id, crm_contacts.office_id AS crm_contacts_office_id, crm_contacts.first_name AS crm_contacts_first_name, crm_contacts.last_name AS crm_contacts_last_name, crm_contacts.email AS crm_contacts_email, crm_contacts.phone AS crm_contacts_phone, crm_contacts.role AS crm_contacts_role, crm_contacts.status AS crm_contacts_status, crm_contacts.source AS crm_contacts_source, crm_contacts.notes AS crm_contacts_notes, crm_contacts.segment AS crm_contacts_segment, crm_contacts.value_score AS crm_contacts_value_score, crm_contacts.tags AS crm_contacts_tags, crm_contacts.created_at AS crm_contacts_created_at, crm_contacts.updated_at AS crm_contacts_updated_at 
FROM crm_contacts 
WHERE crm_contacts.user_id = ? ORDER BY crm_contacts.created_at DESC]
[parameters: (2,)]
(Background on this error at: https://sqlalche.me/e/14/f405)
Traceback:
Traceback (most recent call last):
  File "C:\Users\ustad\Desktop\arsaanalizvesunum\venv\lib\site-packages\sqlalchemy\engine\base.py", line 1910, in _execute_context
    self.dialect.do_execute(
  File "C:\Users\ustad\Desktop\arsaanalizvesunum\venv\lib\site-packages\sqlalchemy\engine\default.py", line 736, in do_execute
    cursor.execute(statement, parameters)
pyodbc.ProgrammingError: ('42S22', "[42S22] [Microsoft][ODBC Driver 18 for SQL Server][SQL Server]Invalid column name 'office_id'. (207) (SQLExecDirectW); [42S22] [Microsoft][ODBC Driver 18 for SQL Server][SQL Server]Statement(s) could not be prepared. (8180)")

The above exception was the direct cause of the following exception:

Traceback (most recent call last):
  File "C:\Users\ustad\Desktop\arsaanalizvesunum\venv\lib\site-packages\flask\app.py", line 1513, in full_dispatch_request
    rv = self.dispatch_request()
  File "C:\Users\ustad\Desktop\arsaanalizvesunum\venv\lib\site-packages\flask\app.py", line 1499, in dispatch_request
    return self.ensure_sync(self.view_functions[rule.endpoint])(**req.view_args)
  File "C:\Users\ustad\Desktop\arsaanalizvesunum\venv\lib\site-packages\flask_login\utils.py", line 290, in decorated_view
    return current_app.ensure_sync(func)(*args, **kwargs)
  File "c:\Users\ustad\Desktop\arsaanalizvesunum\blueprints\main_bp.py", line 190, in index
    son_kisiler = Contact.query.filter_by(user_id=user_id).order_by(Contact.created_at.desc()).limit(5).all()
  File "C:\Users\ustad\Desktop\arsaanalizvesunum\venv\lib\site-packages\sqlalchemy\orm\query.py", line 2773, in all
    return self._iter().all()
  File "C:\Users\ustad\Desktop\arsaanalizvesunum\venv\lib\site-packages\sqlalchemy\orm\query.py", line 2916, in _iter
    result = self.session.execute(
  File "C:\Users\ustad\Desktop\arsaanalizvesunum\venv\lib\site-packages\sqlalchemy\orm\session.py", line 1717, in execute
    result = conn._execute_20(statement, params or {}, execution_options)
  File "C:\Users\ustad\Desktop\arsaanalizvesunum\venv\lib\site-packages\sqlalchemy\engine\base.py", line 1710, in _execute_20
    return meth(self, args_10style, kwargs_10style, execution_options)
  File "C:\Users\ustad\Desktop\arsaanalizvesunum\venv\lib\site-packages\sqlalchemy\sql\elements.py", line 334, in _execute_on_connection
    return connection._execute_clauseelement(
  File "C:\Users\ustad\Desktop\arsaanalizvesunum\venv\lib\site-packages\sqlalchemy\engine\base.py", line 1577, in _execute_clauseelement
    ret = self._execute_context(
  File "C:\Users\ustad\Desktop\arsaanalizvesunum\venv\lib\site-packages\sqlalchemy\engine\base.py", line 1953, in _execute_context
    self._handle_dbapi_exception(
  File "C:\Users\ustad\Desktop\arsaanalizvesunum\venv\lib\site-packages\sqlalchemy\engine\base.py", line 2134, in _handle_dbapi_exception
    util.raise_(
  File "C:\Users\ustad\Desktop\arsaanalizvesunum\venv\lib\site-packages\sqlalchemy\util\compat.py", line 211, in raise_
    raise exception
  File "C:\Users\ustad\Desktop\arsaanalizvesunum\venv\lib\site-packages\sqlalchemy\engine\base.py", line 1910, in _execute_context
    self.dialect.do_execute(
  File "C:\Users\ustad\Desktop\arsaanalizvesunum\venv\lib\site-packages\sqlalchemy\engine\default.py", line 736, in do_execute
    cursor.execute(statement, parameters)
sqlalchemy.exc.ProgrammingError: (pyodbc.ProgrammingError) ('42S22', "[42S22] [Microsoft][ODBC Driver 18 for SQL Server][SQL Server]Invalid column name 'office_id'. (207) (SQLExecDirectW); [42S22] [Microsoft][ODBC Driver 18 for SQL Server][SQL Server]Statement(s) could not be prepared. (8180)")
[SQL: SELECT TOP 5 crm_contacts.id AS crm_contacts_id, crm_contacts.user_id AS crm_contacts_user_id, crm_contacts.company_id AS crm_contacts_company_id, crm_contacts.office_id AS crm_contacts_office_id, crm_contacts.first_name AS crm_contacts_first_name, crm_contacts.last_name AS crm_contacts_last_name, crm_contacts.email AS crm_contacts_email, crm_contacts.phone AS crm_contacts_phone, crm_contacts.role AS crm_contacts_role, crm_contacts.status AS crm_contacts_status, crm_contacts.source AS crm_contacts_source, crm_contacts.notes AS crm_contacts_notes, crm_contacts.segment AS crm_contacts_segment, crm_contacts.value_score AS crm_contacts_value_score, crm_contacts.tags AS crm_contacts_tags, crm_contacts.created_at AS crm_contacts_created_at, crm_contacts.updated_at AS crm_contacts_updated_at 
FROM crm_contacts 
WHERE crm_contacts.user_id = ? ORDER BY crm_contacts.created_at DESC]
[parameters: (2,)]
(Background on this error at: https://sqlalche.me/e/14/f405)

2025-05-19 01:20:06,832 - INFO - app - Flask uygulaması başarıyla oluşturuldu ve yapılandırıldı.
2025-05-19 01:20:19,578 - INFO - app - Flask uygulaması başarıyla oluşturuldu ve yapılandırıldı.
2025-05-19 01:20:21,534 - ERROR - app - Sunucu hatası oluştu: (pyodbc.ProgrammingError) ('42S22', "[42S22] [Microsoft][ODBC Driver 18 for SQL Server][SQL Server]Invalid column name 'office_id'. (207) (SQLExecDirectW); [42S22] [Microsoft][ODBC Driver 18 for SQL Server][SQL Server]Statement(s) could not be prepared. (8180)")
[SQL: SELECT TOP 5 crm_contacts.id AS crm_contacts_id, crm_contacts.user_id AS crm_contacts_user_id, crm_contacts.company_id AS crm_contacts_company_id, crm_contacts.office_id AS crm_contacts_office_id, crm_contacts.first_name AS crm_contacts_first_name, crm_contacts.last_name AS crm_contacts_last_name, crm_contacts.email AS crm_contacts_email, crm_contacts.phone AS crm_contacts_phone, crm_contacts.role AS crm_contacts_role, crm_contacts.status AS crm_contacts_status, crm_contacts.source AS crm_contacts_source, crm_contacts.notes AS crm_contacts_notes, crm_contacts.segment AS crm_contacts_segment, crm_contacts.value_score AS crm_contacts_value_score, crm_contacts.tags AS crm_contacts_tags, crm_contacts.created_at AS crm_contacts_created_at, crm_contacts.updated_at AS crm_contacts_updated_at 
FROM crm_contacts 
WHERE crm_contacts.user_id = ? ORDER BY crm_contacts.created_at DESC]
[parameters: (2,)]
(Background on this error at: https://sqlalche.me/e/14/f405)
Traceback:
Traceback (most recent call last):
  File "C:\Users\ustad\Desktop\arsaanalizvesunum\venv\lib\site-packages\sqlalchemy\engine\base.py", line 1910, in _execute_context
    self.dialect.do_execute(
  File "C:\Users\ustad\Desktop\arsaanalizvesunum\venv\lib\site-packages\sqlalchemy\engine\default.py", line 736, in do_execute
    cursor.execute(statement, parameters)
pyodbc.ProgrammingError: ('42S22', "[42S22] [Microsoft][ODBC Driver 18 for SQL Server][SQL Server]Invalid column name 'office_id'. (207) (SQLExecDirectW); [42S22] [Microsoft][ODBC Driver 18 for SQL Server][SQL Server]Statement(s) could not be prepared. (8180)")

The above exception was the direct cause of the following exception:

Traceback (most recent call last):
  File "C:\Users\ustad\Desktop\arsaanalizvesunum\venv\lib\site-packages\flask\app.py", line 1513, in full_dispatch_request
    rv = self.dispatch_request()
  File "C:\Users\ustad\Desktop\arsaanalizvesunum\venv\lib\site-packages\flask\app.py", line 1499, in dispatch_request
    return self.ensure_sync(self.view_functions[rule.endpoint])(**req.view_args)
  File "C:\Users\ustad\Desktop\arsaanalizvesunum\venv\lib\site-packages\flask_login\utils.py", line 290, in decorated_view
    return current_app.ensure_sync(func)(*args, **kwargs)
  File "c:\Users\ustad\Desktop\arsaanalizvesunum\blueprints\main_bp.py", line 190, in index
    son_kisiler = Contact.query.filter_by(user_id=user_id).order_by(Contact.created_at.desc()).limit(5).all()
  File "C:\Users\ustad\Desktop\arsaanalizvesunum\venv\lib\site-packages\sqlalchemy\orm\query.py", line 2773, in all
    return self._iter().all()
  File "C:\Users\ustad\Desktop\arsaanalizvesunum\venv\lib\site-packages\sqlalchemy\orm\query.py", line 2916, in _iter
    result = self.session.execute(
  File "C:\Users\ustad\Desktop\arsaanalizvesunum\venv\lib\site-packages\sqlalchemy\orm\session.py", line 1717, in execute
    result = conn._execute_20(statement, params or {}, execution_options)
  File "C:\Users\ustad\Desktop\arsaanalizvesunum\venv\lib\site-packages\sqlalchemy\engine\base.py", line 1710, in _execute_20
    return meth(self, args_10style, kwargs_10style, execution_options)
  File "C:\Users\ustad\Desktop\arsaanalizvesunum\venv\lib\site-packages\sqlalchemy\sql\elements.py", line 334, in _execute_on_connection
    return connection._execute_clauseelement(
  File "C:\Users\ustad\Desktop\arsaanalizvesunum\venv\lib\site-packages\sqlalchemy\engine\base.py", line 1577, in _execute_clauseelement
    ret = self._execute_context(
  File "C:\Users\ustad\Desktop\arsaanalizvesunum\venv\lib\site-packages\sqlalchemy\engine\base.py", line 1953, in _execute_context
    self._handle_dbapi_exception(
  File "C:\Users\ustad\Desktop\arsaanalizvesunum\venv\lib\site-packages\sqlalchemy\engine\base.py", line 2134, in _handle_dbapi_exception
    util.raise_(
  File "C:\Users\ustad\Desktop\arsaanalizvesunum\venv\lib\site-packages\sqlalchemy\util\compat.py", line 211, in raise_
    raise exception
  File "C:\Users\ustad\Desktop\arsaanalizvesunum\venv\lib\site-packages\sqlalchemy\engine\base.py", line 1910, in _execute_context
    self.dialect.do_execute(
  File "C:\Users\ustad\Desktop\arsaanalizvesunum\venv\lib\site-packages\sqlalchemy\engine\default.py", line 736, in do_execute
    cursor.execute(statement, parameters)
sqlalchemy.exc.ProgrammingError: (pyodbc.ProgrammingError) ('42S22', "[42S22] [Microsoft][ODBC Driver 18 for SQL Server][SQL Server]Invalid column name 'office_id'. (207) (SQLExecDirectW); [42S22] [Microsoft][ODBC Driver 18 for SQL Server][SQL Server]Statement(s) could not be prepared. (8180)")
[SQL: SELECT TOP 5 crm_contacts.id AS crm_contacts_id, crm_contacts.user_id AS crm_contacts_user_id, crm_contacts.company_id AS crm_contacts_company_id, crm_contacts.office_id AS crm_contacts_office_id, crm_contacts.first_name AS crm_contacts_first_name, crm_contacts.last_name AS crm_contacts_last_name, crm_contacts.email AS crm_contacts_email, crm_contacts.phone AS crm_contacts_phone, crm_contacts.role AS crm_contacts_role, crm_contacts.status AS crm_contacts_status, crm_contacts.source AS crm_contacts_source, crm_contacts.notes AS crm_contacts_notes, crm_contacts.segment AS crm_contacts_segment, crm_contacts.value_score AS crm_contacts_value_score, crm_contacts.tags AS crm_contacts_tags, crm_contacts.created_at AS crm_contacts_created_at, crm_contacts.updated_at AS crm_contacts_updated_at 
FROM crm_contacts 
WHERE crm_contacts.user_id = ? ORDER BY crm_contacts.created_at DESC]
[parameters: (2,)]
(Background on this error at: https://sqlalche.me/e/14/f405)

2025-05-19 01:21:49,209 - ERROR - app - Sunucu hatası oluştu: (pyodbc.ProgrammingError) ('42S22', "[42S22] [Microsoft][ODBC Driver 18 for SQL Server][SQL Server]Invalid column name 'office_id'. (207) (SQLExecDirectW); [42S22] [Microsoft][ODBC Driver 18 for SQL Server][SQL Server]Statement(s) could not be prepared. (8180)")
[SQL: SELECT TOP 5 crm_deals.id AS crm_deals_id, crm_deals.user_id AS crm_deals_user_id, crm_deals.contact_id AS crm_deals_contact_id, crm_deals.company_id AS crm_deals_company_id, crm_deals.office_id AS crm_deals_office_id, crm_deals.title AS crm_deals_title, crm_deals.value AS crm_deals_value, crm_deals.currency AS crm_deals_currency, crm_deals.stage AS crm_deals_stage, crm_deals.expected_close_date AS crm_deals_expected_close_date, crm_deals.actual_close_date AS crm_deals_actual_close_date, crm_deals.probability AS crm_deals_probability, crm_deals.notes AS crm_deals_notes, crm_deals.created_at AS crm_deals_created_at, crm_deals.updated_at AS crm_deals_updated_at 
FROM crm_deals 
WHERE crm_deals.user_id = ? AND (crm_deals.stage NOT IN (?, ?)) ORDER BY crm_deals.created_at DESC]
[parameters: (2, 'Kazanıldı', 'Kaybedildi')]
(Background on this error at: https://sqlalche.me/e/14/f405)
Traceback:
Traceback (most recent call last):
  File "C:\Users\ustad\Desktop\arsaanalizvesunum\venv\lib\site-packages\sqlalchemy\engine\base.py", line 1910, in _execute_context
    self.dialect.do_execute(
  File "C:\Users\ustad\Desktop\arsaanalizvesunum\venv\lib\site-packages\sqlalchemy\engine\default.py", line 736, in do_execute
    cursor.execute(statement, parameters)
pyodbc.ProgrammingError: ('42S22', "[42S22] [Microsoft][ODBC Driver 18 for SQL Server][SQL Server]Invalid column name 'office_id'. (207) (SQLExecDirectW); [42S22] [Microsoft][ODBC Driver 18 for SQL Server][SQL Server]Statement(s) could not be prepared. (8180)")

The above exception was the direct cause of the following exception:

Traceback (most recent call last):
  File "C:\Users\ustad\Desktop\arsaanalizvesunum\venv\lib\site-packages\flask\app.py", line 1513, in full_dispatch_request
    rv = self.dispatch_request()
  File "C:\Users\ustad\Desktop\arsaanalizvesunum\venv\lib\site-packages\flask\app.py", line 1499, in dispatch_request
    return self.ensure_sync(self.view_functions[rule.endpoint])(**req.view_args)
  File "C:\Users\ustad\Desktop\arsaanalizvesunum\venv\lib\site-packages\flask_login\utils.py", line 290, in decorated_view
    return current_app.ensure_sync(func)(*args, **kwargs)
  File "c:\Users\ustad\Desktop\arsaanalizvesunum\blueprints\main_bp.py", line 192, in index
    acik_firsatlar = Deal.query.filter(
  File "C:\Users\ustad\Desktop\arsaanalizvesunum\venv\lib\site-packages\sqlalchemy\orm\query.py", line 2773, in all
    return self._iter().all()
  File "C:\Users\ustad\Desktop\arsaanalizvesunum\venv\lib\site-packages\sqlalchemy\orm\query.py", line 2916, in _iter
    result = self.session.execute(
  File "C:\Users\ustad\Desktop\arsaanalizvesunum\venv\lib\site-packages\sqlalchemy\orm\session.py", line 1717, in execute
    result = conn._execute_20(statement, params or {}, execution_options)
  File "C:\Users\ustad\Desktop\arsaanalizvesunum\venv\lib\site-packages\sqlalchemy\engine\base.py", line 1710, in _execute_20
    return meth(self, args_10style, kwargs_10style, execution_options)
  File "C:\Users\ustad\Desktop\arsaanalizvesunum\venv\lib\site-packages\sqlalchemy\sql\elements.py", line 334, in _execute_on_connection
    return connection._execute_clauseelement(
  File "C:\Users\ustad\Desktop\arsaanalizvesunum\venv\lib\site-packages\sqlalchemy\engine\base.py", line 1577, in _execute_clauseelement
    ret = self._execute_context(
  File "C:\Users\ustad\Desktop\arsaanalizvesunum\venv\lib\site-packages\sqlalchemy\engine\base.py", line 1953, in _execute_context
    self._handle_dbapi_exception(
  File "C:\Users\ustad\Desktop\arsaanalizvesunum\venv\lib\site-packages\sqlalchemy\engine\base.py", line 2134, in _handle_dbapi_exception
    util.raise_(
  File "C:\Users\ustad\Desktop\arsaanalizvesunum\venv\lib\site-packages\sqlalchemy\util\compat.py", line 211, in raise_
    raise exception
  File "C:\Users\ustad\Desktop\arsaanalizvesunum\venv\lib\site-packages\sqlalchemy\engine\base.py", line 1910, in _execute_context
    self.dialect.do_execute(
  File "C:\Users\ustad\Desktop\arsaanalizvesunum\venv\lib\site-packages\sqlalchemy\engine\default.py", line 736, in do_execute
    cursor.execute(statement, parameters)
sqlalchemy.exc.ProgrammingError: (pyodbc.ProgrammingError) ('42S22', "[42S22] [Microsoft][ODBC Driver 18 for SQL Server][SQL Server]Invalid column name 'office_id'. (207) (SQLExecDirectW); [42S22] [Microsoft][ODBC Driver 18 for SQL Server][SQL Server]Statement(s) could not be prepared. (8180)")
[SQL: SELECT TOP 5 crm_deals.id AS crm_deals_id, crm_deals.user_id AS crm_deals_user_id, crm_deals.contact_id AS crm_deals_contact_id, crm_deals.company_id AS crm_deals_company_id, crm_deals.office_id AS crm_deals_office_id, crm_deals.title AS crm_deals_title, crm_deals.value AS crm_deals_value, crm_deals.currency AS crm_deals_currency, crm_deals.stage AS crm_deals_stage, crm_deals.expected_close_date AS crm_deals_expected_close_date, crm_deals.actual_close_date AS crm_deals_actual_close_date, crm_deals.probability AS crm_deals_probability, crm_deals.notes AS crm_deals_notes, crm_deals.created_at AS crm_deals_created_at, crm_deals.updated_at AS crm_deals_updated_at 
FROM crm_deals 
WHERE crm_deals.user_id = ? AND (crm_deals.stage NOT IN (?, ?)) ORDER BY crm_deals.created_at DESC]
[parameters: (2, 'Kazanıldı', 'Kaybedildi')]
(Background on this error at: https://sqlalche.me/e/14/f405)

2025-05-19 01:22:20,735 - INFO - app - Flask uygulaması başarıyla oluşturuldu ve yapılandırıldı.
2025-05-19 01:22:27,375 - INFO - app - Flask uygulaması başarıyla oluşturuldu ve yapılandırıldı.
2025-05-19 01:23:07,672 - INFO - app - Flask uygulaması başarıyla oluşturuldu ve yapılandırıldı.
2025-05-19 01:27:39,225 - INFO - app - Flask uygulaması başarıyla oluşturuldu ve yapılandırıldı.
2025-05-19 01:27:43,586 - INFO - app - Flask uygulaması başarıyla oluşturuldu ve yapılandırıldı.
2025-05-19 01:28:01,202 - ERROR - app - Sunucu hatası oluştu: 404 Not Found: The requested URL was not found on the server. If you entered the URL manually please check your spelling and try again.
Traceback:
Traceback (most recent call last):
  File "C:\Users\ustad\Desktop\arsaanalizvesunum\venv\lib\site-packages\flask\app.py", line 1513, in full_dispatch_request
    rv = self.dispatch_request()
  File "C:\Users\ustad\Desktop\arsaanalizvesunum\venv\lib\site-packages\flask\app.py", line 1489, in dispatch_request
    self.raise_routing_exception(req)
  File "C:\Users\ustad\Desktop\arsaanalizvesunum\venv\lib\site-packages\flask\app.py", line 1471, in raise_routing_exception
    raise request.routing_exception  # type: ignore
  File "C:\Users\ustad\Desktop\arsaanalizvesunum\venv\lib\site-packages\flask\ctx.py", line 367, in match_request
    result = self.url_adapter.match(return_rule=True)  # type: ignore
  File "C:\Users\ustad\Desktop\arsaanalizvesunum\venv\lib\site-packages\werkzeug\routing.py", line 2032, in match
    raise NotFound()
werkzeug.exceptions.NotFound: 404 Not Found: The requested URL was not found on the server. If you entered the URL manually please check your spelling and try again.

2025-05-19 01:28:02,853 - ERROR - app - Sunucu hatası oluştu: 404 Not Found: The requested URL was not found on the server. If you entered the URL manually please check your spelling and try again.
Traceback:
Traceback (most recent call last):
  File "C:\Users\ustad\Desktop\arsaanalizvesunum\venv\lib\site-packages\flask\app.py", line 1513, in full_dispatch_request
    rv = self.dispatch_request()
  File "C:\Users\ustad\Desktop\arsaanalizvesunum\venv\lib\site-packages\flask\app.py", line 1499, in dispatch_request
    return self.ensure_sync(self.view_functions[rule.endpoint])(**req.view_args)
  File "C:\Users\ustad\Desktop\arsaanalizvesunum\venv\lib\site-packages\flask\app.py", line 518, in <lambda>
    view_func=lambda **kw: self_ref().send_static_file(**kw),  # type: ignore # noqa: B950
  File "C:\Users\ustad\Desktop\arsaanalizvesunum\venv\lib\site-packages\flask\scaffold.py", line 328, in send_static_file
    return send_from_directory(
  File "C:\Users\ustad\Desktop\arsaanalizvesunum\venv\lib\site-packages\flask\helpers.py", line 700, in send_from_directory
    return werkzeug.utils.send_from_directory(  # type: ignore
  File "C:\Users\ustad\Desktop\arsaanalizvesunum\venv\lib\site-packages\werkzeug\utils.py", line 841, in send_from_directory
    raise NotFound()
werkzeug.exceptions.NotFound: 404 Not Found: The requested URL was not found on the server. If you entered the URL manually please check your spelling and try again.

2025-05-19 01:28:06,109 - ERROR - app - Sunucu hatası oluştu: 404 Not Found: The requested URL was not found on the server. If you entered the URL manually please check your spelling and try again.
Traceback:
Traceback (most recent call last):
  File "C:\Users\ustad\Desktop\arsaanalizvesunum\venv\lib\site-packages\flask\app.py", line 1513, in full_dispatch_request
    rv = self.dispatch_request()
  File "C:\Users\ustad\Desktop\arsaanalizvesunum\venv\lib\site-packages\flask\app.py", line 1489, in dispatch_request
    self.raise_routing_exception(req)
  File "C:\Users\ustad\Desktop\arsaanalizvesunum\venv\lib\site-packages\flask\app.py", line 1471, in raise_routing_exception
    raise request.routing_exception  # type: ignore
  File "C:\Users\ustad\Desktop\arsaanalizvesunum\venv\lib\site-packages\flask\ctx.py", line 367, in match_request
    result = self.url_adapter.match(return_rule=True)  # type: ignore
  File "C:\Users\ustad\Desktop\arsaanalizvesunum\venv\lib\site-packages\werkzeug\routing.py", line 2032, in match
    raise NotFound()
werkzeug.exceptions.NotFound: 404 Not Found: The requested URL was not found on the server. If you entered the URL manually please check your spelling and try again.

2025-05-19 01:28:07,621 - ERROR - app - Sunucu hatası oluştu: 404 Not Found: The requested URL was not found on the server. If you entered the URL manually please check your spelling and try again.
Traceback:
Traceback (most recent call last):
  File "C:\Users\ustad\Desktop\arsaanalizvesunum\venv\lib\site-packages\flask\app.py", line 1513, in full_dispatch_request
    rv = self.dispatch_request()
  File "C:\Users\ustad\Desktop\arsaanalizvesunum\venv\lib\site-packages\flask\app.py", line 1489, in dispatch_request
    self.raise_routing_exception(req)
  File "C:\Users\ustad\Desktop\arsaanalizvesunum\venv\lib\site-packages\flask\app.py", line 1471, in raise_routing_exception
    raise request.routing_exception  # type: ignore
  File "C:\Users\ustad\Desktop\arsaanalizvesunum\venv\lib\site-packages\flask\ctx.py", line 367, in match_request
    result = self.url_adapter.match(return_rule=True)  # type: ignore
  File "C:\Users\ustad\Desktop\arsaanalizvesunum\venv\lib\site-packages\werkzeug\routing.py", line 2032, in match
    raise NotFound()
werkzeug.exceptions.NotFound: 404 Not Found: The requested URL was not found on the server. If you entered the URL manually please check your spelling and try again.

2025-05-19 01:28:10,264 - ERROR - app - Sunucu hatası oluştu: 404 Not Found: The requested URL was not found on the server. If you entered the URL manually please check your spelling and try again.
Traceback:
Traceback (most recent call last):
  File "C:\Users\ustad\Desktop\arsaanalizvesunum\venv\lib\site-packages\flask\app.py", line 1513, in full_dispatch_request
    rv = self.dispatch_request()
  File "C:\Users\ustad\Desktop\arsaanalizvesunum\venv\lib\site-packages\flask\app.py", line 1489, in dispatch_request
    self.raise_routing_exception(req)
  File "C:\Users\ustad\Desktop\arsaanalizvesunum\venv\lib\site-packages\flask\app.py", line 1471, in raise_routing_exception
    raise request.routing_exception  # type: ignore
  File "C:\Users\ustad\Desktop\arsaanalizvesunum\venv\lib\site-packages\flask\ctx.py", line 367, in match_request
    result = self.url_adapter.match(return_rule=True)  # type: ignore
  File "C:\Users\ustad\Desktop\arsaanalizvesunum\venv\lib\site-packages\werkzeug\routing.py", line 2032, in match
    raise NotFound()
werkzeug.exceptions.NotFound: 404 Not Found: The requested URL was not found on the server. If you entered the URL manually please check your spelling and try again.

2025-05-19 01:28:11,393 - ERROR - app - Sunucu hatası oluştu: 404 Not Found: The requested URL was not found on the server. If you entered the URL manually please check your spelling and try again.
Traceback:
Traceback (most recent call last):
  File "C:\Users\ustad\Desktop\arsaanalizvesunum\venv\lib\site-packages\flask\app.py", line 1513, in full_dispatch_request
    rv = self.dispatch_request()
  File "C:\Users\ustad\Desktop\arsaanalizvesunum\venv\lib\site-packages\flask\app.py", line 1489, in dispatch_request
    self.raise_routing_exception(req)
  File "C:\Users\ustad\Desktop\arsaanalizvesunum\venv\lib\site-packages\flask\app.py", line 1471, in raise_routing_exception
    raise request.routing_exception  # type: ignore
  File "C:\Users\ustad\Desktop\arsaanalizvesunum\venv\lib\site-packages\flask\ctx.py", line 367, in match_request
    result = self.url_adapter.match(return_rule=True)  # type: ignore
  File "C:\Users\ustad\Desktop\arsaanalizvesunum\venv\lib\site-packages\werkzeug\routing.py", line 2032, in match
    raise NotFound()
werkzeug.exceptions.NotFound: 404 Not Found: The requested URL was not found on the server. If you entered the URL manually please check your spelling and try again.

2025-05-19 01:28:14,460 - ERROR - app - Sunucu hatası oluştu: 404 Not Found: The requested URL was not found on the server. If you entered the URL manually please check your spelling and try again.
Traceback:
Traceback (most recent call last):
  File "C:\Users\ustad\Desktop\arsaanalizvesunum\venv\lib\site-packages\flask\app.py", line 1513, in full_dispatch_request
    rv = self.dispatch_request()
  File "C:\Users\ustad\Desktop\arsaanalizvesunum\venv\lib\site-packages\flask\app.py", line 1489, in dispatch_request
    self.raise_routing_exception(req)
  File "C:\Users\ustad\Desktop\arsaanalizvesunum\venv\lib\site-packages\flask\app.py", line 1471, in raise_routing_exception
    raise request.routing_exception  # type: ignore
  File "C:\Users\ustad\Desktop\arsaanalizvesunum\venv\lib\site-packages\flask\ctx.py", line 367, in match_request
    result = self.url_adapter.match(return_rule=True)  # type: ignore
  File "C:\Users\ustad\Desktop\arsaanalizvesunum\venv\lib\site-packages\werkzeug\routing.py", line 2032, in match
    raise NotFound()
werkzeug.exceptions.NotFound: 404 Not Found: The requested URL was not found on the server. If you entered the URL manually please check your spelling and try again.

